Workbook

Sheet apostol
A1: Читання | B1: Книга | C1: Книга_код | D1: # зач. | E1: abc | F1: Присвята | G1: Примітка | H1: Дата (мінея) | I1: Період | J1: Тиждень від | K1: Тиждень до ВП | L1: День тижня | M1: Обч. день тижня | N1: Обч. період | O1: Обч. тиждень | P1: empty?
A2: Ді. 1 зач.; 1, 1-8. | B2: =LEFT(A2,FIND(".",A2)) -> Ді. | C2: ap | D2: =MID(A2,FIND(".",A2)+2,FIND(" ",RIGHT(A2,LEN(A2)-FIND(".",A2)-1))-1) -> 1 | E2: a | F2: В святу й велику неділю Пасхи | I2: lent | J2: 7 | L2: 7 | M2: =IFNA( VLOOKUP(LEFT(F2, IFERROR(FIND(" ", F2, 1),1) - 1), lists!$A$31:$B$37, 2, FALSE),"") | N2: =IFERROR(__xludf.DUMMYFUNCTION("IFNA(VLOOKUP(IFNA(REGEXEXTRACT(F2, ""(Пасхи|50-ці|посту)""),""""),lists!$A$39:$B$41,2,FALSE),"""")"),"pascha") -> pascha | O2: =IFERROR(__xludf.DUMMYFUNCTION("IFNA(REGEXEXTRACT(F2, ""\d{1,2}""),"""")"),"") | P2: =AND(OR(I2="",J2="",L2=""),H2="") -> FALSE
A3: Ді. 1 зач.; 1, 1-12. | B3: =LEFT(A3,FIND(".",A3)) -> Ді. | C3: ap | D3: =MID(A3,FIND(".",A3)+2,FIND(" ",RIGHT(A3,LEN(A3)-FIND(".",A3)-1))-1) -> 1 | E3: b | F3: На Вознесення Господнє | I3: pascha | J3: 6 | L3: 4 | M3: =IFNA( VLOOKUP(LEFT(F3, IFERROR(FIND(" ", F3, 1),1) - 1), lists!$A$31:$B$37, 2, FALSE),"") | N3: =IFERROR(__xludf.DUMMYFUNCTION("IFNA(VLOOKUP(IFNA(REGEXEXTRACT(F3, ""(Пасхи|50-ці|посту)""),""""),lists!$A$39:$B$41,2,FALSE),"""")"),"") | O3: =IFERROR(__xludf.DUMMYFUNCTION("IFNA(REGEXEXTRACT(F3, ""\d{1,2}""),"""")"),"") | P3: =AND(OR(I3="",J3="",L3=""),H3="") -> FALSE
A4: Ді. 2 зач.; 1, 12-17; 21-26. | B4: =LEFT(A4,FIND(".",A4)) -> Ді. | C4: ap | D4: =MID(A4,FIND(".",A4)+2,FIND(" ",RIGHT(A4,LEN(A4)-FIND(".",A4)-1))-1) -> 2 | F4: Понеділок світлого тижня. Цей і ап. Матію | I4: pascha | J4: 1 | L4: 1 | M4: =IFNA( VLOOKUP(LEFT(F4, IFERROR(FIND(" ", F4, 1),1) - 1), lists!$A$31:$B$37, 2, FALSE),"") -> 1 | N4: =IFERROR(__xludf.DUMMYFUNCTION("IFNA(VLOOKUP(IFNA(REGEXEXTRACT(F4, ""(Пасхи|50-ці|посту)""),""""),lists!$A$39:$B$41,2,FALSE),"""")"),"") | O4: =IFERROR(__xludf.DUMMYFUNCTION("IFNA(REGEXEXTRACT(F4, ""\d{1,2}""),"""")"),"") | P4: =AND(OR(I4="",J4="",L4=""),H4="") -> FALSE
A5: Ді. 3 зач.; 2, 1-11. | B5: =LEFT(A5,FIND(".",A5)) -> Ді. | C5: ap | D5: =MID(A5,FIND(".",A5)+2,FIND(" ",RIGHT(A5,LEN(A5)-FIND(".",A5)-1))-1) -> 3 | F5: Неділя 50-ці | I5: pentecost | J5: 7 | L5: 7 | M5: =IFNA( VLOOKUP(LEFT(F5, IFERROR(FIND(" ", F5, 1),1) - 1), lists!$A$31:$B$37, 2, FALSE),"") -> 7 | N5: =IFERROR(__xludf.DUMMYFUNCTION("IFNA(VLOOKUP(IFNA(REGEXEXTRACT(F5, ""(Пасхи|50-ці|посту)""),""""),lists!$A$39:$B$41,2,FALSE),"""")"),"pentecost") -> pentecost | O5: =IFERROR(__xludf.DUMMYFUNCTION("IFNA(REGEXEXTRACT(F5, ""\d{1,2}""),"""")"),"50") -> 50 | P5: =AND(OR(I5="",J5="",L5=""),H5="") -> FALSE
A6: Ді. 4 зач.; 2, 14-21. | B6: =LEFT(A6,FIND(".",A6)) -> Ді. | C6: ap | D6: =MID(A6,FIND(".",A6)+2,FIND(" ",RIGHT(A6,LEN(A6)-FIND(".",A6)-1))-1) -> 4 | F6: Вівторок світлого тижня | I6: pascha | J6: 1 | L6: 2 | M6: =IFNA( VLOOKUP(LEFT(F6, IFERROR(FIND(" ", F6, 1),1) - 1), lists!$A$31:$B$37, 2, FALSE),"") -> 2 | N6: =IFERROR(__xludf.DUMMYFUNCTION("IFNA(VLOOKUP(IFNA(REGEXEXTRACT(F6, ""(Пасхи|50-ці|посту)""),""""),lists!$A$39:$B$41,2,FALSE),"""")"),"") | O6: =IFERROR(__xludf.DUMMYFUNCTION("IFNA(REGEXEXTRACT(F6, ""\d{1,2}""),"""")"),"") | P6: =AND(OR(I6="",J6="",L6=""),H6="") -> FALSE
A7: Ді. 5 зач.; 2, 22-36. | B7: =LEFT(A7,FIND(".",A7)) -> Ді. | C7: ap | D7: =MID(A7,FIND(".",A7)+2,FIND(" ",RIGHT(A7,LEN(A7)-FIND(".",A7)-1))-1) -> 5 | F7: Середа світлого тижня | I7: pascha | J7: 1 | L7: 3 | M7: =IFNA( VLOOKUP(LEFT(F7, IFERROR(FIND(" ", F7, 1),1) - 1), lists!$A$31:$B$37, 2, FALSE),"") -> 3 | N7: =IFERROR(__xludf.DUMMYFUNCTION("IFNA(VLOOKUP(IFNA(REGEXEXTRACT(F7, ""(Пасхи|50-ці|посту)""),""""),lists!$A$39:$B$41,2,FALSE),"""")"),"") | O7: =IFERROR(__xludf.DUMMYFUNCTION("IFNA(REGEXEXTRACT(F7, ""\d{1,2}""),"""")"),"") | P7: =AND(OR(I7="",J7="",L7=""),H7="") -> FALSE
A8: Ді. 6 зач.; 2, 38-43. | B8: =LEFT(A8,FIND(".",A8)) -> Ді. | C8: ap | D8: =MID(A8,FIND(".",A8)+2,FIND(" ",RIGHT(A8,LEN(A8)-FIND(".",A8)-1))-1) -> 6 | F8: Четвер світлого тижня | I8: pascha | J8: 1 | L8: 4 | M8: =IFNA( VLOOKUP(LEFT(F8, IFERROR(FIND(" ", F8, 1),1) - 1), lists!$A$31:$B$37, 2, FALSE),"") -> 4 | N8: =IFERROR(__xludf.DUMMYFUNCTION("IFNA(VLOOKUP(IFNA(REGEXEXTRACT(F8, ""(Пасхи|50-ці|посту)""),""""),lists!$A$39:$B$41,2,FALSE),"""")"),"") | O8: =IFERROR(__xludf.DUMMYFUNCTION("IFNA(REGEXEXTRACT(F8, ""\d{1,2}""),"""")"),"") | P8: =AND(OR(I8="",J8="",L8=""),H8="") -> FALSE
A9: Ді. 7 зач.; 3, 1-8. | B9: =LEFT(A9,FIND(".",A9)) -> Ді. | C9: ap | D9: =MID(A9,FIND(".",A9)+2,FIND(" ",RIGHT(A9,LEN(A9)-FIND(".",A9)-1))-1) -> 7 | F9: П'ятниця світлого тижня | I9: pascha | J9: 1 | L9: 5 | M9: =IFNA( VLOOKUP(LEFT(F9, IFERROR(FIND(" ", F9, 1),1) - 1), lists!$A$31:$B$37, 2, FALSE),"") -> 5 | N9: =IFERROR(__xludf.DUMMYFUNCTION("IFNA(VLOOKUP(IFNA(REGEXEXTRACT(F9, ""(Пасхи|50-ці|посту)""),""""),lists!$A$39:$B$41,2,FALSE),"""")"),"") | O9: =IFERROR(__xludf.DUMMYFUNCTION("IFNA(REGEXEXTRACT(F9, ""\d{1,2}""),"""")"),"") | P9: =AND(OR(I9="",J9="",L9=""),H9="") -> FALSE
A10: Ді. 8 зач.; 3, 11-16. | B10: =LEFT(A10,FIND(".",A10)) -> Ді. | C10: ap | D10: =MID(A10,FIND(".",A10)+2,FIND(" ",RIGHT(A10,LEN(A10)-FIND(".",A10)-1))-1) -> 8 | F10: Субота світлого тижня | I10: pascha | J10: 1 | L10: 6 | M10: =IFNA( VLOOKUP(LEFT(F10, IFERROR(FIND(" ", F10, 1),1) - 1), lists!$A$31:$B$37, 2, FALSE),"") -> 6 | N10: =IFERROR(__xludf.DUMMYFUNCTION("IFNA(VLOOKUP(IFNA(REGEXEXTRACT(F10, ""(Пасхи|50-ці|посту)""),""""),lists!$A$39:$B$41,2,FALSE),"""")"),"") | O10: =IFERROR(__xludf.DUMMYFUNCTION("IFNA(REGEXEXTRACT(F10, ""\d{1,2}""),"""")"),"") | P10: =AND(OR(I10="",J10="",L10=""),H10="") -> FALSE
A11: Ді. 9 зач.; 3, 19-26. | B11: =LEFT(A11,FIND(".",A11)) -> Ді. | C11: ap | D11: =MID(A11,FIND(".",A11)+2,FIND(" ",RIGHT(A11,LEN(A11)-FIND(".",A11)-1))-1) -> 9 | F11: Понеділок 2-го тижня після Пасхи | I11: pascha | J11: 2 | L11: 1 | M11: =IFNA( VLOOKUP(LEFT(F11, IFERROR(FIND(" ", F11, 1),1) - 1), lists!$A$31:$B$37, 2, FALSE),"") -> 1 | N11: =IFERROR(__xludf.DUMMYFUNCTION("IFNA(VLOOKUP(IFNA(REGEXEXTRACT(F11, ""(Пасхи|50-ці|посту)""),""""),lists!$A$39:$B$41,2,FALSE),"""")"),"pascha") -> pascha | O11: =IFERROR(__xludf.DUMMYFUNCTION("IFNA(REGEXEXTRACT(F11, ""\d{1,2}""),"""")"),"2") -> 2 | P11: =AND(OR(I11="",J11="",L11=""),H11="") -> FALSE
A12: Ді. 10 зач.; 4, 1-10. | B12: =LEFT(A12,FIND(".",A12)) -> Ді. | C12: ap | D12: =MID(A12,FIND(".",A12)+2,FIND(" ",RIGHT(A12,LEN(A12)-FIND(".",A12)-1))-1) -> 10 | F12: Вівторок 2-го тижня після Пасхи | I12: pascha | J12: 2 | L12: 2 | M12: =IFNA( VLOOKUP(LEFT(F12, IFERROR(FIND(" ", F12, 1),1) - 1), lists!$A$31:$B$37, 2, FALSE),"") -> 2 | N12: =IFERROR(__xludf.DUMMYFUNCTION("IFNA(VLOOKUP(IFNA(REGEXEXTRACT(F12, ""(Пасхи|50-ці|посту)""),""""),lists!$A$39:$B$41,2,FALSE),"""")"),"pascha") -> pascha | O12: =IFERROR(__xludf.DUMMYFUNCTION("IFNA(REGEXEXTRACT(F12, ""\d{1,2}""),"""")"),"2") -> 2 | P12: =AND(OR(I12="",J12="",L12=""),H12="") -> FALSE
A13: Ді. 11 зач.; 4, 13-22. | B13: =LEFT(A13,FIND(".",A13)) -> Ді. | C13: ap | D13: =MID(A13,FIND(".",A13)+2,FIND(" ",RIGHT(A13,LEN(A13)-FIND(".",A13)-1))-1) -> 11 | F13: Середа 2-го тижня після Пасхи | I13: pascha | J13: 2 | L13: 3 | M13: =IFNA( VLOOKUP(LEFT(F13, IFERROR(FIND(" ", F13, 1),1) - 1), lists!$A$31:$B$37, 2, FALSE),"") -> 3 | N13: =IFERROR(__xludf.DUMMYFUNCTION("IFNA(VLOOKUP(IFNA(REGEXEXTRACT(F13, ""(Пасхи|50-ці|посту)""),""""),lists!$A$39:$B$41,2,FALSE),"""")"),"pascha") -> pascha | O13: =IFERROR(__xludf.DUMMYFUNCTION("IFNA(REGEXEXTRACT(F13, ""\d{1,2}""),"""")"),"2") -> 2 | P13: =AND(OR(I13="",J13="",L13=""),H13="") -> FALSE
A14: Ді. 12 зач.; 4, 23-31. | B14: =LEFT(A14,FIND(".",A14)) -> Ді. | C14: ap | D14: =MID(A14,FIND(".",A14)+2,FIND(" ",RIGHT(A14,LEN(A14)-FIND(".",A14)-1))-1) -> 12 | F14: Четвер 2-го тижня після Пасхи | I14: pascha | J14: 2 | L14: 4 | M14: =IFNA( VLOOKUP(LEFT(F14, IFERROR(FIND(" ", F14, 1),1) - 1), lists!$A$31:$B$37, 2, FALSE),"") -> 4 | N14: =IFERROR(__xludf.DUMMYFUNCTION("IFNA(VLOOKUP(IFNA(REGEXEXTRACT(F14, ""(Пасхи|50-ці|посту)""),""""),lists!$A$39:$B$41,2,FALSE),"""")"),"pascha") -> pascha | O14: =IFERROR(__xludf.DUMMYFUNCTION("IFNA(REGEXEXTRACT(F14, ""\d{1,2}""),"""")"),"2") -> 2 | P14: =AND(OR(I14="",J14="",L14=""),H14="") -> FALSE
A15: Ді. 13 зач.; 5, 1-11. | B15: =LEFT(A15,FIND(".",A15)) -> Ді. | C15: ap | D15: =MID(A15,FIND(".",A15)+2,FIND(" ",RIGHT(A15,LEN(A15)-FIND(".",A15)-1))-1) -> 13 | F15: П'ятниця 2-го тижня після Пасхи | I15: pascha | J15: 2 | L15: 5 | M15: =IFNA( VLOOKUP(LEFT(F15, IFERROR(FIND(" ", F15, 1),1) - 1), lists!$A$31:$B$37, 2, FALSE),"") -> 5 | N15: =IFERROR(__xludf.DUMMYFUNCTION("IFNA(VLOOKUP(IFNA(REGEXEXTRACT(F15, ""(Пасхи|50-ці|посту)""),""""),lists!$A$39:$B$41,2,FALSE),"""")"),"pascha") -> pascha | O15: =IFERROR(__xludf.DUMMYFUNCTION("IFNA(REGEXEXTRACT(F15, ""\d{1,2}""),"""")"),"2") -> 2 | P15: =AND(OR(I15="",J15="",L15=""),H15="") -> FALSE
A16: Ді. 14 зач.; 5, 12-20. | B16: =LEFT(A16,FIND(".",A16)) -> Ді. | C16: ap | D16: =MID(A16,FIND(".",A16)+2,FIND(" ",RIGHT(A16,LEN(A16)-FIND(".",A16)-1))-1) -> 14 | F16: Томина неділя | I16: pascha | J16: 1 | L16: 7 | M16: =IFNA( VLOOKUP(LEFT(F16, IFERROR(FIND(" ", F16, 1),1) - 1), lists!$A$31:$B$37, 2, FALSE),"") | N16: =IFERROR(__xludf.DUMMYFUNCTION("IFNA(VLOOKUP(IFNA(REGEXEXTRACT(F16, ""(Пасхи|50-ці|посту)""),""""),lists!$A$39:$B$41,2,FALSE),"""")"),"") | O16: =IFERROR(__xludf.DUMMYFUNCTION("IFNA(REGEXEXTRACT(F16, ""\d{1,2}""),"""")"),"") | P16: =AND(OR(I16="",J16="",L16=""),H16="") -> FALSE
A17: Ді. 15 зач.; 5, 21-33. | B17: =LEFT(A17,FIND(".",A17)) -> Ді. | C17: ap | D17: =MID(A17,FIND(".",A17)+2,FIND(" ",RIGHT(A17,LEN(A17)-FIND(".",A17)-1))-1) -> 15 | F17: Субота 2-го тижня після Пасхи | I17: pascha | J17: 2 | L17: 6 | M17: =IFNA( VLOOKUP(LEFT(F17, IFERROR(FIND(" ", F17, 1),1) - 1), lists!$A$31:$B$37, 2, FALSE),"") -> 6 | N17: =IFERROR(__xludf.DUMMYFUNCTION("IFNA(VLOOKUP(IFNA(REGEXEXTRACT(F17, ""(Пасхи|50-ці|посту)""),""""),lists!$A$39:$B$41,2,FALSE),"""")"),"pascha") -> pascha | O17: =IFERROR(__xludf.DUMMYFUNCTION("IFNA(REGEXEXTRACT(F17, ""\d{1,2}""),"""")"),"2") -> 2 | P17: =AND(OR(I17="",J17="",L17=""),H17="") -> FALSE
A18: Ді. 16 зач.; 6, 1-7. | B18: =LEFT(A18,FIND(".",A18)) -> Ді. | C18: ap | D18: =MID(A18,FIND(".",A18)+2,FIND(" ",RIGHT(A18,LEN(A18)-FIND(".",A18)-1))-1) -> 16 | F18: Неділя 3-тя після Пасхи | I18: pascha | J18: 3 | L18: 7 | M18: =IFNA( VLOOKUP(LEFT(F18, IFERROR(FIND(" ", F18, 1),1) - 1), lists!$A$31:$B$37, 2, FALSE),"") -> 7 | N18: =IFERROR(__xludf.DUMMYFUNCTION("IFNA(VLOOKUP(IFNA(REGEXEXTRACT(F18, ""(Пасхи|50-ці|посту)""),""""),lists!$A$39:$B$41,2,FALSE),"""")"),"pascha") -> pascha | O18: =IFERROR(__xludf.DUMMYFUNCTION("IFNA(REGEXEXTRACT(F18, ""\d{1,2}""),"""")"),"3") -> 3 | P18: =AND(OR(I18="",J18="",L18=""),H18="") -> FALSE
A19: Ді. 17 зач.; 6, 8 – 7, 5; 47-60. | B19: =LEFT(A19,FIND(".",A19)) -> Ді. | C19: ap | D19: =MID(A19,FIND(".",A19)+2,FIND(" ",RIGHT(A19,LEN(A19)-FIND(".",A19)-1))-1) -> 17 | F19: Понеділок 3-го тижня після Пасхи. Цей і святому Стефанові первомученику | I19: pascha | J19: 3 | L19: 1 | M19: =IFNA( VLOOKUP(LEFT(F19, IFERROR(FIND(" ", F19, 1),1) - 1), lists!$A$31:$B$37, 2, FALSE),"") -> 1 | N19: =IFERROR(__xludf.DUMMYFUNCTION("IFNA(VLOOKUP(IFNA(REGEXEXTRACT(F19, ""(Пасхи|50-ці|посту)""),""""),lists!$A$39:$B$41,2,FALSE),"""")"),"pascha") -> pascha | O19: =IFERROR(__xludf.DUMMYFUNCTION("IFNA(REGEXEXTRACT(F19, ""\d{1,2}""),"""")"),"3") -> 3 | P19: =AND(OR(I19="",J19="",L19=""),H19="") -> FALSE
A20: Ді. 18 зач.; 8, 5-17. | B20: =LEFT(A20,FIND(".",A20)) -> Ді. | C20: ap | D20: =MID(A20,FIND(".",A20)+2,FIND(" ",RIGHT(A20,LEN(A20)-FIND(".",A20)-1))-1) -> 18 | F20: Вівторок 3-го тижня після Пасхи | I20: pascha | J20: 3 | L20: 2 | M20: =IFNA( VLOOKUP(LEFT(F20, IFERROR(FIND(" ", F20, 1),1) - 1), lists!$A$31:$B$37, 2, FALSE),"") -> 2 | N20: =IFERROR(__xludf.DUMMYFUNCTION("IFNA(VLOOKUP(IFNA(REGEXEXTRACT(F20, ""(Пасхи|50-ці|посту)""),""""),lists!$A$39:$B$41,2,FALSE),"""")"),"pascha") -> pascha | O20: =IFERROR(__xludf.DUMMYFUNCTION("IFNA(REGEXEXTRACT(F20, ""\d{1,2}""),"""")"),"3") -> 3 | P20: =AND(OR(I20="",J20="",L20=""),H20="") -> FALSE
A21: Ді. 19 зач.; 8, 18-25. | B21: =LEFT(A21,FIND(".",A21)) -> Ді. | C21: ap | D21: =MID(A21,FIND(".",A21)+2,FIND(" ",RIGHT(A21,LEN(A21)-FIND(".",A21)-1))-1) -> 19 | F21: Середа 3-го тижня після Пасхи | I21: pascha | J21: 3 | L21: 3 | M21: =IFNA( VLOOKUP(LEFT(F21, IFERROR(FIND(" ", F21, 1),1) - 1), lists!$A$31:$B$37, 2, FALSE),"") -> 3 | N21: =IFERROR(__xludf.DUMMYFUNCTION("IFNA(VLOOKUP(IFNA(REGEXEXTRACT(F21, ""(Пасхи|50-ці|посту)""),""""),lists!$A$39:$B$41,2,FALSE),"""")"),"pascha") -> pascha | O21: =IFERROR(__xludf.DUMMYFUNCTION("IFNA(REGEXEXTRACT(F21, ""\d{1,2}""),"""")"),"3") -> 3 | P21: =AND(OR(I21="",J21="",L21=""),H21="") -> FALSE
A22: Ді. 20 зач.; 8, 26-39. | B22: =LEFT(A22,FIND(".",A22)) -> Ді. | C22: ap | D22: =MID(A22,FIND(".",A22)+2,FIND(" ",RIGHT(A22,LEN(A22)-FIND(".",A22)-1))-1) -> 20 | F22: Четвер 3-го тижня після Пасхи | I22: pascha | J22: 3 | L22: 4 | M22: =IFNA( VLOOKUP(LEFT(F22, IFERROR(FIND(" ", F22, 1),1) - 1), lists!$A$31:$B$37, 2, FALSE),"") -> 4 | N22: =IFERROR(__xludf.DUMMYFUNCTION("IFNA(VLOOKUP(IFNA(REGEXEXTRACT(F22, ""(Пасхи|50-ці|посту)""),""""),lists!$A$39:$B$41,2,FALSE),"""")"),"pascha") -> pascha | O22: =IFERROR(__xludf.DUMMYFUNCTION("IFNA(REGEXEXTRACT(F22, ""\d{1,2}""),"""")"),"3") -> 3 | P22: =AND(OR(I22="",J22="",L22=""),H22="") -> FALSE
A23: Ді. 21 зач.; 8, 40 – 9, 19. | B23: =LEFT(A23,FIND(".",A23)) -> Ді. | C23: ap | D23: =MID(A23,FIND(".",A23)+2,FIND(" ",RIGHT(A23,LEN(A23)-FIND(".",A23)-1))-1) -> 21 | E23: a | F23: П'ятниця 3-го тижня після Пасхи | I23: pascha | J23: 3 | L23: 5 | M23: =IFNA( VLOOKUP(LEFT(F23, IFERROR(FIND(" ", F23, 1),1) - 1), lists!$A$31:$B$37, 2, FALSE),"") -> 5 | N23: =IFERROR(__xludf.DUMMYFUNCTION("IFNA(VLOOKUP(IFNA(REGEXEXTRACT(F23, ""(Пасхи|50-ці|посту)""),""""),lists!$A$39:$B$41,2,FALSE),"""")"),"pascha") -> pascha | O23: =IFERROR(__xludf.DUMMYFUNCTION("IFNA(REGEXEXTRACT(F23, ""\d{1,2}""),"""")"),"3") -> 3 | P23: =AND(OR(I23="",J23="",L23=""),H23="") -> FALSE
A24: Ді. 21 зач.; 9, 10-19. | B24: =LEFT(A24,FIND(".",A24)) -> Ді. | C24: ap | D24: =MID(A24,FIND(".",A24)+2,FIND(" ",RIGHT(A24,LEN(A24)-FIND(".",A24)-1))-1) -> 21 | E24: b | F24: ап. Ананії | H24: * | M24: =IFNA( VLOOKUP(LEFT(F24, IFERROR(FIND(" ", F24, 1),1) - 1), lists!$A$31:$B$37, 2, FALSE),"") | N24: =IFERROR(__xludf.DUMMYFUNCTION("IFNA(VLOOKUP(IFNA(REGEXEXTRACT(F24, ""(Пасхи|50-ці|посту)""),""""),lists!$A$39:$B$41,2,FALSE),"""")"),"") | O24: =IFERROR(__xludf.DUMMYFUNCTION("IFNA(REGEXEXTRACT(F24, ""\d{1,2}""),"""")"),"") | P24: =AND(OR(I24="",J24="",L24=""),H24="") -> FALSE
A25: Ді. 22 зач.; 9, 20-31. | B25: =LEFT(A25,FIND(".",A25)) -> Ді. | C25: ap | D25: =MID(A25,FIND(".",A25)+2,FIND(" ",RIGHT(A25,LEN(A25)-FIND(".",A25)-1))-1) -> 22 | F25: Субота 3-тя після Пасхи | I25: pascha | J25: 3 | L25: 6 | M25: =IFNA( VLOOKUP(LEFT(F25, IFERROR(FIND(" ", F25, 1),1) - 1), lists!$A$31:$B$37, 2, FALSE),"") -> 6 | N25: =IFERROR(__xludf.DUMMYFUNCTION("IFNA(VLOOKUP(IFNA(REGEXEXTRACT(F25, ""(Пасхи|50-ці|посту)""),""""),lists!$A$39:$B$41,2,FALSE),"""")"),"pascha") -> pascha | O25: =IFERROR(__xludf.DUMMYFUNCTION("IFNA(REGEXEXTRACT(F25, ""\d{1,2}""),"""")"),"3") -> 3 | P25: =AND(OR(I25="",J25="",L25=""),H25="") -> FALSE
A26: Ді. 23 зач.; 9, 32-42. | B26: =LEFT(A26,FIND(".",A26)) -> Ді. | C26: ap | D26: =MID(A26,FIND(".",A26)+2,FIND(" ",RIGHT(A26,LEN(A26)-FIND(".",A26)-1))-1) -> 23 | F26: Неділя 4-та, про розслабленого | I26: pascha | J26: 3 | L26: 7 | M26: =IFNA( VLOOKUP(LEFT(F26, IFERROR(FIND(" ", F26, 1),1) - 1), lists!$A$31:$B$37, 2, FALSE),"") -> 7 | N26: =IFERROR(__xludf.DUMMYFUNCTION("IFNA(VLOOKUP(IFNA(REGEXEXTRACT(F26, ""(Пасхи|50-ці|посту)""),""""),lists!$A$39:$B$41,2,FALSE),"""")"),"") | O26: =IFERROR(__xludf.DUMMYFUNCTION("IFNA(REGEXEXTRACT(F26, ""\d{1,2}""),"""")"),"4") -> 4 | P26: =AND(OR(I26="",J26="",L26=""),H26="") -> FALSE
A27: Ді. 24 зач.; 10, 1-16. | B27: =LEFT(A27,FIND(".",A27)) -> Ді. | C27: ap | D27: =MID(A27,FIND(".",A27)+2,FIND(" ",RIGHT(A27,LEN(A27)-FIND(".",A27)-1))-1) -> 24 | F27: Понеділок 4-го тижня після Пасхи | I27: pascha | J27: 4 | L27: 1 | M27: =IFNA( VLOOKUP(LEFT(F27, IFERROR(FIND(" ", F27, 1),1) - 1), lists!$A$31:$B$37, 2, FALSE),"") -> 1 | N27: =IFERROR(__xludf.DUMMYFUNCTION("IFNA(VLOOKUP(IFNA(REGEXEXTRACT(F27, ""(Пасхи|50-ці|посту)""),""""),lists!$A$39:$B$41,2,FALSE),"""")"),"pascha") -> pascha | O27: =IFERROR(__xludf.DUMMYFUNCTION("IFNA(REGEXEXTRACT(F27, ""\d{1,2}""),"""")"),"4") -> 4 | P27: =AND(OR(I27="",J27="",L27=""),H27="") -> FALSE
A28: Ді. 25 зач.; 10, 21-33. | B28: =LEFT(A28,FIND(".",A28)) -> Ді. | C28: ap | D28: =MID(A28,FIND(".",A28)+2,FIND(" ",RIGHT(A28,LEN(A28)-FIND(".",A28)-1))-1) -> 25 | F28: Вівторок 4-го тижня після Пасхи | I28: pascha | J28: 4 | L28: 2 | M28: =IFNA( VLOOKUP(LEFT(F28, IFERROR(FIND(" ", F28, 1),1) - 1), lists!$A$31:$B$37, 2, FALSE),"") -> 2 | N28: =IFERROR(__xludf.DUMMYFUNCTION("IFNA(VLOOKUP(IFNA(REGEXEXTRACT(F28, ""(Пасхи|50-ці|посту)""),""""),lists!$A$39:$B$41,2,FALSE),"""")"),"pascha") -> pascha | O28: =IFERROR(__xludf.DUMMYFUNCTION("IFNA(REGEXEXTRACT(F28, ""\d{1,2}""),"""")"),"4") -> 4 | P28: =AND(OR(I28="",J28="",L28=""),H28="") -> FALSE
A29: Ді. 26 зач.; 10, 34-43. | B29: =LEFT(A29,FIND(".",A29)) -> Ді. | C29: ap | D29: =MID(A29,FIND(".",A29)+2,FIND(" ",RIGHT(A29,LEN(A29)-FIND(".",A29)-1))-1) -> 26 | F29: Четвер 4-го тижня після Пасхи | I29: pascha | J29: 4 | L29: 4 | M29: =IFNA( VLOOKUP(LEFT(F29, IFERROR(FIND(" ", F29, 1),1) - 1), lists!$A$31:$B$37, 2, FALSE),"") -> 4 | N29: =IFERROR(__xludf.DUMMYFUNCTION("IFNA(VLOOKUP(IFNA(REGEXEXTRACT(F29, ""(Пасхи|50-ці|посту)""),""""),lists!$A$39:$B$41,2,FALSE),"""")"),"pascha") -> pascha | O29: =IFERROR(__xludf.DUMMYFUNCTION("IFNA(REGEXEXTRACT(F29, ""\d{1,2}""),"""")"),"4") -> 4 | P29: =AND(OR(I29="",J29="",L29=""),H29="") -> FALSE
A30: Ді. 27 зач.; 10, 44 – 11, 10. | B30: =LEFT(A30,FIND(".",A30)) -> Ді. | C30: ap | D30: =MID(A30,FIND(".",A30)+2,FIND(" ",RIGHT(A30,LEN(A30)-FIND(".",A30)-1))-1) -> 27 | F30: П'ятниця 4-го тижня після Пасхи | I30: pascha | J30: 4 | L30: 5 | M30: =IFNA( VLOOKUP(LEFT(F30, IFERROR(FIND(" ", F30, 1),1) - 1), lists!$A$31:$B$37, 2, FALSE),"") -> 5 | N30: =IFERROR(__xludf.DUMMYFUNCTION("IFNA(VLOOKUP(IFNA(REGEXEXTRACT(F30, ""(Пасхи|50-ці|посту)""),""""),lists!$A$39:$B$41,2,FALSE),"""")"),"pascha") -> pascha | O30: =IFERROR(__xludf.DUMMYFUNCTION("IFNA(REGEXEXTRACT(F30, ""\d{1,2}""),"""")"),"4") -> 4 | P30: =AND(OR(I30="",J30="",L30=""),H30="") -> FALSE
A31: Ді. 28 зач.; 11, 19-26; 29-30. | B31: =LEFT(A31,FIND(".",A31)) -> Ді. | C31: ap | D31: =MID(A31,FIND(".",A31)+2,FIND(" ",RIGHT(A31,LEN(A31)-FIND(".",A31)-1))-1) -> 28 | F31: Неділя 5-та, про самарянку. Цей же і Вартоломею та Варнаві | I31: pascha | J31: 4 | L31: 7 | M31: =IFNA( VLOOKUP(LEFT(F31, IFERROR(FIND(" ", F31, 1),1) - 1), lists!$A$31:$B$37, 2, FALSE),"") -> 7 | N31: =IFERROR(__xludf.DUMMYFUNCTION("IFNA(VLOOKUP(IFNA(REGEXEXTRACT(F31, ""(Пасхи|50-ці|посту)""),""""),lists!$A$39:$B$41,2,FALSE),"""")"),"") | O31: =IFERROR(__xludf.DUMMYFUNCTION("IFNA(REGEXEXTRACT(F31, ""\d{1,2}""),"""")"),"5") -> 5 | P31: =AND(OR(I31="",J31="",L31=""),H31="") -> FALSE
A32: Ді. 29 зач.; 12, 1-11. | B32: =LEFT(A32,FIND(".",A32)) -> Ді. | C32: ap | D32: =MID(A32,FIND(".",A32)+2,FIND(" ",RIGHT(A32,LEN(A32)-FIND(".",A32)-1))-1) -> 29 | F32: Субота 4-та після Пасихи. Цей же і святому мученикові Юрієві, і Яковові Заведеєві | H32: * | J32: 4 | L32: 6 | M32: =IFNA( VLOOKUP(LEFT(F32, IFERROR(FIND(" ", F32, 1),1) - 1), lists!$A$31:$B$37, 2, FALSE),"") -> 6 | N32: =IFERROR(__xludf.DUMMYFUNCTION("IFNA(VLOOKUP(IFNA(REGEXEXTRACT(F32, ""(Пасхи|50-ці|посту)""),""""),lists!$A$39:$B$41,2,FALSE),"""")"),"") | O32: =IFERROR(__xludf.DUMMYFUNCTION("IFNA(REGEXEXTRACT(F32, ""\d{1,2}""),"""")"),"4") -> 4 | P32: =AND(OR(I32="",J32="",L32=""),H32="") -> FALSE
A33: Ді. 30 зач.; 12, 12-17. | B33: =LEFT(A33,FIND(".",A33)) -> Ді. | C33: ap | D33: =MID(A33,FIND(".",A33)+2,FIND(" ",RIGHT(A33,LEN(A33)-FIND(".",A33)-1))-1) -> 30 | F33: Понеділок 5-го тижня після Пасхи | I33: pascha | J33: 5 | L33: 1 | M33: =IFNA( VLOOKUP(LEFT(F33, IFERROR(FIND(" ", F33, 1),1) - 1), lists!$A$31:$B$37, 2, FALSE),"") -> 1 | N33: =IFERROR(__xludf.DUMMYFUNCTION("IFNA(VLOOKUP(IFNA(REGEXEXTRACT(F33, ""(Пасхи|50-ці|посту)""),""""),lists!$A$39:$B$41,2,FALSE),"""")"),"pascha") -> pascha | O33: =IFERROR(__xludf.DUMMYFUNCTION("IFNA(REGEXEXTRACT(F33, ""\d{1,2}""),"""")"),"5") -> 5 | P33: =AND(OR(I33="",J33="",L33=""),H33="") -> FALSE
A34: Ді. 31 зач.; 12, 25 – 13, 12. | B34: =LEFT(A34,FIND(".",A34)) -> Ді. | C34: ap | D34: =MID(A34,FIND(".",A34)+2,FIND(" ",RIGHT(A34,LEN(A34)-FIND(".",A34)-1))-1) -> 31 | F34: Вівторок 5-го тижня після Пасхи | I34: pascha | J34: 5 | L34: 2 | M34: =IFNA( VLOOKUP(LEFT(F34, IFERROR(FIND(" ", F34, 1),1) - 1), lists!$A$31:$B$37, 2, FALSE),"") -> 2 | N34: =IFERROR(__xludf.DUMMYFUNCTION("IFNA(VLOOKUP(IFNA(REGEXEXTRACT(F34, ""(Пасхи|50-ці|посту)""),""""),lists!$A$39:$B$41,2,FALSE),"""")"),"pascha") -> pascha | O34: =IFERROR(__xludf.DUMMYFUNCTION("IFNA(REGEXEXTRACT(F34, ""\d{1,2}""),"""")"),"5") -> 5 | P34: =AND(OR(I34="",J34="",L34=""),H34="") -> FALSE
A35: Ді. 32 зач.; 13, 13-24. | B35: =LEFT(A35,FIND(".",A35)) -> Ді. | C35: ap | D35: =MID(A35,FIND(".",A35)+2,FIND(" ",RIGHT(A35,LEN(A35)-FIND(".",A35)-1))-1) -> 32 | F35: Середа 5-го тижня після Пасхи | I35: pascha | J35: 5 | L35: 3 | M35: =IFNA( VLOOKUP(LEFT(F35, IFERROR(FIND(" ", F35, 1),1) - 1), lists!$A$31:$B$37, 2, FALSE),"") -> 3 | N35: =IFERROR(__xludf.DUMMYFUNCTION("IFNA(VLOOKUP(IFNA(REGEXEXTRACT(F35, ""(Пасхи|50-ці|посту)""),""""),lists!$A$39:$B$41,2,FALSE),"""")"),"pascha") -> pascha | O35: =IFERROR(__xludf.DUMMYFUNCTION("IFNA(REGEXEXTRACT(F35, ""\d{1,2}""),"""")"),"5") -> 5 | P35: =AND(OR(I35="",J35="",L35=""),H35="") -> FALSE
A36: Ді. 33 зач.; 13, 25-33. | B36: =LEFT(A36,FIND(".",A36)) -> Ді. | C36: ap | D36: =MID(A36,FIND(".",A36)+2,FIND(" ",RIGHT(A36,LEN(A36)-FIND(".",A36)-1))-1) -> 33 | F36: Усікновення голови св. Івана Христителя | H36: * | M36: =IFNA( VLOOKUP(LEFT(F36, IFERROR(FIND(" ", F36, 1),1) - 1), lists!$A$31:$B$37, 2, FALSE),"") | N36: =IFERROR(__xludf.DUMMYFUNCTION("IFNA(VLOOKUP(IFNA(REGEXEXTRACT(F36, ""(Пасхи|50-ці|посту)""),""""),lists!$A$39:$B$41,2,FALSE),"""")"),"") | O36: =IFERROR(__xludf.DUMMYFUNCTION("IFNA(REGEXEXTRACT(F36, ""\d{1,2}""),"""")"),"") | P36: =AND(OR(I36="",J36="",L36=""),H36="") -> FALSE
A37: Ді. 34 зач.; 14, 6-18. | B37: =LEFT(A37,FIND(".",A37)) -> Ді. | C37: ap | D37: =MID(A37,FIND(".",A37)+2,FIND(" ",RIGHT(A37,LEN(A37)-FIND(".",A37)-1))-1) -> 34 | F37: Середа Переполовення | I37: pascha | J37: 4 | L37: 3 | M37: =IFNA( VLOOKUP(LEFT(F37, IFERROR(FIND(" ", F37, 1),1) - 1), lists!$A$31:$B$37, 2, FALSE),"") -> 3 | N37: =IFERROR(__xludf.DUMMYFUNCTION("IFNA(VLOOKUP(IFNA(REGEXEXTRACT(F37, ""(Пасхи|50-ці|посту)""),""""),lists!$A$39:$B$41,2,FALSE),"""")"),"") | O37: =IFERROR(__xludf.DUMMYFUNCTION("IFNA(REGEXEXTRACT(F37, ""\d{1,2}""),"""")"),"") | P37: =AND(OR(I37="",J37="",L37=""),H37="") -> FALSE
A38: Ді. 35 зач.; 14, 20-27. | B38: =LEFT(A38,FIND(".",A38)) -> Ді. | C38: ap | D38: =MID(A38,FIND(".",A38)+2,FIND(" ",RIGHT(A38,LEN(A38)-FIND(".",A38)-1))-1) -> 35 | F38: Четвер 5-го тижня після Пасхи | I38: pascha | J38: 5 | L38: 4 | M38: =IFNA( VLOOKUP(LEFT(F38, IFERROR(FIND(" ", F38, 1),1) - 1), lists!$A$31:$B$37, 2, FALSE),"") -> 4 | N38: =IFERROR(__xludf.DUMMYFUNCTION("IFNA(VLOOKUP(IFNA(REGEXEXTRACT(F38, ""(Пасхи|50-ці|посту)""),""""),lists!$A$39:$B$41,2,FALSE),"""")"),"pascha") -> pascha | O38: =IFERROR(__xludf.DUMMYFUNCTION("IFNA(REGEXEXTRACT(F38, ""\d{1,2}""),"""")"),"5") -> 5 | P38: =AND(OR(I38="",J38="",L38=""),H38="") -> FALSE
A39: Ді. 36 зач.; 15, 5-34. | B39: =LEFT(A39,FIND(".",A39)) -> Ді. | C39: ap | D39: =MID(A39,FIND(".",A39)+2,FIND(" ",RIGHT(A39,LEN(A39)-FIND(".",A39)-1))-1) -> 36 | F39: П'ятниця 5-го тижня після Пасхи | I39: pascha | J39: 5 | L39: 5 | M39: =IFNA( VLOOKUP(LEFT(F39, IFERROR(FIND(" ", F39, 1),1) - 1), lists!$A$31:$B$37, 2, FALSE),"") -> 5 | N39: =IFERROR(__xludf.DUMMYFUNCTION("IFNA(VLOOKUP(IFNA(REGEXEXTRACT(F39, ""(Пасхи|50-ці|посту)""),""""),lists!$A$39:$B$41,2,FALSE),"""")"),"pascha") -> pascha | O39: =IFERROR(__xludf.DUMMYFUNCTION("IFNA(REGEXEXTRACT(F39, ""\d{1,2}""),"""")"),"5") -> 5 | P39: =AND(OR(I39="",J39="",L39=""),H39="") -> FALSE
A40: Ді. 37 зач.; 15, 35-41. | B40: =LEFT(A40,FIND(".",A40)) -> Ді. | C40: ap | D40: =MID(A40,FIND(".",A40)+2,FIND(" ",RIGHT(A40,LEN(A40)-FIND(".",A40)-1))-1) -> 37 | F40: Субота 5-го тижня після Пасхи | I40: pascha | J40: 5 | L40: 6 | M40: =IFNA( VLOOKUP(LEFT(F40, IFERROR(FIND(" ", F40, 1),1) - 1), lists!$A$31:$B$37, 2, FALSE),"") -> 6 | N40: =IFERROR(__xludf.DUMMYFUNCTION("IFNA(VLOOKUP(IFNA(REGEXEXTRACT(F40, ""(Пасхи|50-ці|посту)""),""""),lists!$A$39:$B$41,2,FALSE),"""")"),"pascha") -> pascha | O40: =IFERROR(__xludf.DUMMYFUNCTION("IFNA(REGEXEXTRACT(F40, ""\d{1,2}""),"""")"),"5") -> 5 | P40: =AND(OR(I40="",J40="",L40=""),H40="") -> FALSE
...

Sheet apostol_triodion
A1: Читання | B1: Книга | C1: # зач. | D1: abc | E1: Присвята | F1: Примітка | G1: Дата (мінея) | H1: Період | I1: Тиждень від | J1: Тиждень до ВП | K1: День тижня | L1: empty?
A2: Євр. 303 зач.; 1, 1-12. | B2: =LEFT(A2,FIND(".",A2)) -> Євр. | C2: =MID(A2,FIND(".",A2)+2,FIND(" ",RIGHT(A2,LEN(A2)-FIND(".",A2)-1))-1) -> 303 | E2: Перша субота посту. Цей і в навечір'я Різдва Христового | H2: lent | I2: 1 | K2: 6 | L2: =AND(OR(H2="",I2="",K2=""),G2="") -> FALSE
A3: Євр. 329 зач.; 11, 24-26; 32 – 12, 2. | B3: =LEFT(A3,FIND(".",A3)) -> Євр. | C3: =MID(A3,FIND(".",A3)+2,FIND(" ",RIGHT(A3,LEN(A3)-FIND(".",A3)-1))-1) -> 329 | D3: b | E3: Перша неділя посту, православія | H3: lent | I3: 1 | K3: 7 | L3: =AND(OR(H3="",I3="",K3=""),G3="") -> FALSE
A4: Євр. 309 зач.; 3, 12-16. | B4: =LEFT(A4,FIND(".",A4)) -> Євр. | C4: =MID(A4,FIND(".",A4)+2,FIND(" ",RIGHT(A4,LEN(A4)-FIND(".",A4)-1))-1) -> 309 | E4: Друга субота посту | H4: lent | I4: 2 | K4: 6 | L4: =AND(OR(H4="",I4="",K4=""),G4="") -> FALSE
A5: Євр. 304 зач.; 1, 10 – 2, 3. | B5: =LEFT(A5,FIND(".",A5)) -> Євр. | C5: =MID(A5,FIND(".",A5)+2,FIND(" ",RIGHT(A5,LEN(A5)-FIND(".",A5)-1))-1) -> 304 | E5: Друга неділя посту | H5: lent | I5: 2 | K5: 7 | L5: =AND(OR(H5="",I5="",K5=""),G5="") -> FALSE
A6: Євр. 325 зач.; 10, 32-38. | B6: =LEFT(A6,FIND(".",A6)) -> Євр. | C6: =MID(A6,FIND(".",A6)+2,FIND(" ",RIGHT(A6,LEN(A6)-FIND(".",A6)-1))-1) -> 325 | E6: Третя субота посту | H6: lent | I6: 3 | K6: 6 | L6: =AND(OR(H6="",I6="",K6=""),G6="") -> FALSE
A7: Євр. 311 зач.; 4, 14 – 5, 6. | B7: =LEFT(A7,FIND(".",A7)) -> Євр. | C7: =MID(A7,FIND(".",A7)+2,FIND(" ",RIGHT(A7,LEN(A7)-FIND(".",A7)-1))-1) -> 311 | D7: a | E7: Третя неділя посту | H7: lent | I7: 3 | K7: 7 | L7: =AND(OR(H7="",I7="",K7=""),G7="") -> FALSE
A8: Євр. 313 зач.; 6, 9-12. | B8: =LEFT(A8,FIND(".",A8)) -> Євр. | C8: =MID(A8,FIND(".",A8)+2,FIND(" ",RIGHT(A8,LEN(A8)-FIND(".",A8)-1))-1) -> 313 | E8: Четверта субота посту | H8: lent | I8: 4 | K8: 6 | L8: =AND(OR(H8="",I8="",K8=""),G8="") -> FALSE
A9: Євр. 314 зач.; 6, 13-20. | B9: =LEFT(A9,FIND(".",A9)) -> Євр. | C9: =MID(A9,FIND(".",A9)+2,FIND(" ",RIGHT(A9,LEN(A9)-FIND(".",A9)-1))-1) -> 314 | E9: Четверта неділя посту | H9: lent | I9: 4 | K9: 7 | L9: =AND(OR(H9="",I9="",K9=""),G9="") -> FALSE
A10: Євр. 322 зач.; 9, 24-28. | B10: =LEFT(A10,FIND(".",A10)) -> Євр. | C10: =MID(A10,FIND(".",A10)+2,FIND(" ",RIGHT(A10,LEN(A10)-FIND(".",A10)-1))-1) -> 322 | E10: П'ята субота посту | H10: lent | I10: 5 | K10: 6 | L10: =AND(OR(H10="",I10="",K10=""),G10="") -> FALSE
A11: Євр. 321 зач.; 9, 11-14. | B11: =LEFT(A11,FIND(".",A11)) -> Євр. | C11: =MID(A11,FIND(".",A11)+2,FIND(" ",RIGHT(A11,LEN(A11)-FIND(".",A11)-1))-1) -> 321 | D11: b | E11: П'ята неділя посту. Цей і Симеону Богоприємцеві | G11: * | H11: lent | I11: 5 | K11: 7 | L11: =AND(OR(H11="",I11="",K11=""),G11="") -> FALSE
A12: Євр. 333 зач.; 12, 28 – 13, 8. | B12: =LEFT(A12,FIND(".",A12)) -> Євр. | C12: =MID(A12,FIND(".",A12)+2,FIND(" ",RIGHT(A12,LEN(A12)-FIND(".",A12)-1))-1) -> 333 | D12: b | E12: Шоста субота посту, квітна | H12: lent | I12: 6 | K12: 6 | L12: =AND(OR(H12="",I12="",K12=""),G12="") -> FALSE
A13: Флп. 247 зач.; 4, 4-9. | B13: =LEFT(A13,FIND(".",A13)) -> Флп. | C13: =MID(A13,FIND(".",A13)+2,FIND(" ",RIGHT(A13,LEN(A13)-FIND(".",A13)-1))-1) -> 247 | E13: Квітна неділя | H13: lent | I13: 6 | K13: 7 | L13: =AND(OR(H13="",I13="",K13=""),G13="") -> FALSE
A14: 1 Кор. 149 зач.; 11, 23-32. | B14: =LEFT(A14,FIND(".",A14)) -> 1 Кор. | C14: =MID(A14,FIND(".",A14)+2,FIND(" ",RIGHT(A14,LEN(A14)-FIND(".",A14)-1))-1) -> 149 | E14: У Великий четвер | H14: lent | I14: 7 | K14: 4 | L14: =AND(OR(H14="",I14="",K14=""),G14="") -> FALSE
A15: 1 Кор. 125 зач.; 1, 18 – 2, 2. | B15: =LEFT(A15,FIND(".",A15)) -> 1 Кор. | C15: =MID(A15,FIND(".",A15)+2,FIND(" ",RIGHT(A15,LEN(A15)-FIND(".",A15)-1))-1) -> 125 | D15: a | E15: Велика п'ятниця | H15: lent | I15: 7 | K15: 5 | L15: =AND(OR(H15="",I15="",K15=""),G15="") -> FALSE
A16: Рим. 91 зач.; 6, 3-11. | B16: =LEFT(A16,FIND(".",A16)) -> Рим. | C16: =MID(A16,FIND(".",A16)+2,FIND(" ",RIGHT(A16,LEN(A16)-FIND(".",A16)-1))-1) -> 91 | E16: Свята й Велика субота вечора | H16: lent | I16: 7 | K16: 6 | L16: =AND(OR(H16="",I16="",K16=""),G16="") -> FALSE
A17: Ді. 1 зач.; 1, 1-8. | B17: =LEFT(A17,FIND(".",A17)) -> Ді. | C17: =MID(A17,FIND(".",A17)+2,FIND(" ",RIGHT(A17,LEN(A17)-FIND(".",A17)-1))-1) -> 1 | D17: a | E17: В святу й велику неділю Пасхи | H17: pascha | I17: 1 | K17: 0 | L17: =AND(OR(H17="",I17="",K17=""),G17="") -> FALSE
A18: Ді. 2 зач.; 1, 12-17; 21-26. | B18: =LEFT(A18,FIND(".",A18)) -> Ді. | C18: =MID(A18,FIND(".",A18)+2,FIND(" ",RIGHT(A18,LEN(A18)-FIND(".",A18)-1))-1) -> 2 | E18: Понеділок світлого тижня | H18: pascha | I18: 1 | K18: 1 | L18: =AND(OR(H18="",I18="",K18=""),G18="") -> FALSE
A19: Ді. 4 зач.; 2, 14-21. | B19: =LEFT(A19,FIND(".",A19)) -> Ді. | C19: =MID(A19,FIND(".",A19)+2,FIND(" ",RIGHT(A19,LEN(A19)-FIND(".",A19)-1))-1) -> 4 | E19: Вівторок світлого тижня | H19: pascha | I19: 1 | K19: 2 | L19: =AND(OR(H19="",I19="",K19=""),G19="") -> FALSE
A20: Ді. 5 зач.; 2, 22-36. | B20: =LEFT(A20,FIND(".",A20)) -> Ді. | C20: =MID(A20,FIND(".",A20)+2,FIND(" ",RIGHT(A20,LEN(A20)-FIND(".",A20)-1))-1) -> 5 | E20: Середа світлого тижня | H20: pascha | I20: 1 | K20: 3 | L20: =AND(OR(H20="",I20="",K20=""),G20="") -> FALSE
A21: Ді. 6 зач.; 2, 38-43. | B21: =LEFT(A21,FIND(".",A21)) -> Ді. | C21: =MID(A21,FIND(".",A21)+2,FIND(" ",RIGHT(A21,LEN(A21)-FIND(".",A21)-1))-1) -> 6 | E21: Четвер світлого тижня | H21: pascha | I21: 1 | K21: 4 | L21: =AND(OR(H21="",I21="",K21=""),G21="") -> FALSE
A22: Ді. 7 зач.; 3, 1-8. | B22: =LEFT(A22,FIND(".",A22)) -> Ді. | C22: =MID(A22,FIND(".",A22)+2,FIND(" ",RIGHT(A22,LEN(A22)-FIND(".",A22)-1))-1) -> 7 | E22: П'ятниця світлого тижня | H22: pascha | I22: 1 | K22: 5 | L22: =AND(OR(H22="",I22="",K22=""),G22="") -> FALSE
A23: Ді. 8 зач.; 3, 11-16. | B23: =LEFT(A23,FIND(".",A23)) -> Ді. | C23: =MID(A23,FIND(".",A23)+2,FIND(" ",RIGHT(A23,LEN(A23)-FIND(".",A23)-1))-1) -> 8 | E23: Субота світлого тижня | H23: pascha | I23: 1 | K23: 6 | L23: =AND(OR(H23="",I23="",K23=""),G23="") -> FALSE
A24: Ді. 14 зач.; 5, 12-20. | B24: =LEFT(A24,FIND(".",A24)) -> Ді. | C24: =MID(A24,FIND(".",A24)+2,FIND(" ",RIGHT(A24,LEN(A24)-FIND(".",A24)-1))-1) -> 14 | E24: Томина неділя | H24: pascha | I24: 2 | K24: 0 | L24: =AND(OR(H24="",I24="",K24=""),G24="") -> FALSE
A25: Ді. 9 зач.; 3, 19-26. | B25: =LEFT(A25,FIND(".",A25)) -> Ді. | C25: =MID(A25,FIND(".",A25)+2,FIND(" ",RIGHT(A25,LEN(A25)-FIND(".",A25)-1))-1) -> 9 | E25: Понеділок 2-го тижня після Пасхи | H25: pascha | I25: 2 | K25: 1 | L25: =AND(OR(H25="",I25="",K25=""),G25="") -> FALSE
A26: Ді. 10 зач.; 4, 1-10. | B26: =LEFT(A26,FIND(".",A26)) -> Ді. | C26: =MID(A26,FIND(".",A26)+2,FIND(" ",RIGHT(A26,LEN(A26)-FIND(".",A26)-1))-1) -> 10 | E26: Вівторок 2-го тижня після Пасхи | H26: pascha | I26: 2 | K26: 2 | L26: =AND(OR(H26="",I26="",K26=""),G26="") -> FALSE
A27: Ді. 11 зач.; 4, 13-22. | B27: =LEFT(A27,FIND(".",A27)) -> Ді. | C27: =MID(A27,FIND(".",A27)+2,FIND(" ",RIGHT(A27,LEN(A27)-FIND(".",A27)-1))-1) -> 11 | E27: Середа 2-го тижня після Пасхи | H27: pascha | I27: 2 | K27: 3 | L27: =AND(OR(H27="",I27="",K27=""),G27="") -> FALSE
A28: Ді. 12 зач.; 4, 23-31. | B28: =LEFT(A28,FIND(".",A28)) -> Ді. | C28: =MID(A28,FIND(".",A28)+2,FIND(" ",RIGHT(A28,LEN(A28)-FIND(".",A28)-1))-1) -> 12 | E28: Четвер 2-го тижня після Пасхи | H28: pascha | I28: 2 | K28: 4 | L28: =AND(OR(H28="",I28="",K28=""),G28="") -> FALSE
A29: Ді. 13 зач.; 5, 1-11. | B29: =LEFT(A29,FIND(".",A29)) -> Ді. | C29: =MID(A29,FIND(".",A29)+2,FIND(" ",RIGHT(A29,LEN(A29)-FIND(".",A29)-1))-1) -> 13 | E29: П'ятниця 2-го тижня після Пасхи | H29: pascha | I29: 2 | K29: 5 | L29: =AND(OR(H29="",I29="",K29=""),G29="") -> FALSE
... A35: Ді. 20 зач.; 8, 26-39. | B35: =LEFT(A35,FIND(".",A35)) -> Ді. | C35: =MID(A35,FIND(".",A35)+2,FIND(" ",RIGHT(A35,LEN(A35)-FIND(".",A35)-1))-1) -> 20 | E35: Четвер 3-го тижня після Пасхи | H35: pascha | I35: 3 | K35: 4 | L35: =AND(OR(H35="",I35="",K35=""),G35="") -> FALSE
A36: Ді. 21 зач.; 8, 40 – 9, 19. | B36: =LEFT(A36,FIND(".",A36)) -> Ді. | C36: =MID(A36,FIND(".",A36)+2,FIND(" ",RIGHT(A36,LEN(A36)-FIND(".",A36)-1))-1) -> 21 | D36: a | E36: П'ятниця 3-го тижня після Пасхи | H36: pascha | I36: 3 | K36: 5 | L36: =AND(OR(H36="",I36="",K36=""),G36="") -> FALSE
A37: Ді. 22 зач.; 9, 20-31. | B37: =LEFT(A37,FIND(".",A37)) -> Ді. | C37: =MID(A37,FIND(".",A37)+2,FIND(" ",RIGHT(A37,LEN(A37)-FIND(".",A37)-1))-1) -> 22 | E37: Субота 3-тя після Пасхи | H37: pascha | I37: 3 | K37: 6 | L37: =AND(OR(H37="",I37="",K37=""),G37="") -> FALSE
A38: Ді. 23 зач.; 9, 32-42. | B38: =LEFT(A38,FIND(".",A38)) -> Ді. | C38: =MID(A38,FIND(".",A38)+2,FIND(" ",RIGHT(A38,LEN(A38)-FIND(".",A38)-1))-1) -> 23 | E38: Неділя 4-та, про розслабленого | H38: pascha | I38: 4 | K38: 0 | L38: =AND(OR(H38="",I38="",K38=""),G38="") -> FALSE
A39: Ді. 24 зач.; 10, 1-16. | B39: =LEFT(A39,FIND(".",A39)) -> Ді. | C39: =MID(A39,FIND(".",A39)+2,FIND(" ",RIGHT(A39,LEN(A39)-FIND(".",A39)-1))-1) -> 24 | E39: Понеділок 4-го тижня після Пасхи | H39: pascha | I39: 4 | K39: 1 | L39: =AND(OR(H39="",I39="",K39=""),G39="") -> FALSE
A40: Ді. 25 зач.; 10, 21-33. | B40: =LEFT(A40,FIND(".",A40)) -> Ді. | C40: =MID(A40,FIND(".",A40)+2,FIND(" ",RIGHT(A40,LEN(A40)-FIND(".",A40)-1))-1) -> 25 | E40: Вівторок 4-го тижня після Пасхи | H40: pascha | I40: 4 | K40: 2 | L40: =AND(OR(H40="",I40="",K40=""),G40="") -> FALSE
A41: Ді. 34 зач.; 14, 6-18. | B41: =LEFT(A41,FIND(".",A41)) -> Ді. | C41: =MID(A41,FIND(".",A41)+2,FIND(" ",RIGHT(A41,LEN(A41)-FIND(".",A41)-1))-1) -> 34 | E41: Середа Переполовення | H41: pascha | I41: 4 | K41: 3 | L41: =AND(OR(H41="",I41="",K41=""),G41="") -> FALSE
A42: Ді. 26 зач.; 10, 34-43. | B42: =LEFT(A42,FIND(".",A42)) -> Ді. | C42: =MID(A42,FIND(".",A42)+2,FIND(" ",RIGHT(A42,LEN(A42)-FIND(".",A42)-1))-1) -> 26 | E42: Четвер 4-го тижня після Пасхи | H42: pascha | I42: 4 | K42: 4 | L42: =AND(OR(H42="",I42="",K42=""),G42="") -> FALSE
A43: Ді. 27 зач.; 10, 44 – 11, 10. | B43: =LEFT(A43,FIND(".",A43)) -> Ді. | C43: =MID(A43,FIND(".",A43)+2,FIND(" ",RIGHT(A43,LEN(A43)-FIND(".",A43)-1))-1) -> 27 | E43: П'ятниця 4-го тижня після Пасхи | H43: pascha | I43: 4 | K43: 5 | L43: =AND(OR(H43="",I43="",K43=""),G43="") -> FALSE
A44: Ді. 29 зач.; 12, 1-11. | B44: =LEFT(A44,FIND(".",A44)) -> Ді. | C44: =MID(A44,FIND(".",A44)+2,FIND(" ",RIGHT(A44,LEN(A44)-FIND(".",A44)-1))-1) -> 29 | E44: Субота 4-та після Пасхи. Цей же і святому мученикові Юрієві, і Яковові Заведеєві | H44: pascha | I44: 4 | K44: 6 | L44: =AND(OR(H44="",I44="",K44=""),G44="") -> FALSE
A45: Ді. 28 зач.; 11, 19-26; 29-30. | B45: =LEFT(A45,FIND(".",A45)) -> Ді. | C45: =MID(A45,FIND(".",A45)+2,FIND(" ",RIGHT(A45,LEN(A45)-FIND(".",A45)-1))-1) -> 28 | E45: Неділя 5-та, про самарянку | H45: pascha | I45: 5 | K45: 0 | L45: =AND(OR(H45="",I45="",K45=""),G45="") -> FALSE
...

Sheet evanhelie
A1: Читання | B1: Книга | C1: Книга_код | D1: # зач. | E1: abc | F1: Присвята | G1: Примітка | H1: Дата (мінея) | I1: Період | J1: Тиждень від | K1: Тиждень до ВП | L1: День тижня | M1: Обч. день тижня | N1: Обч. період | O1: Обч. тиждень | P1: empty?
A2: Ів. 1 зач.; 1, 1-17. | B2: =LEFT(A2,FIND(".",A2)) -> Ів. | C2: iv | D2: =MID(A2,FIND(".",A2)+2,FIND(" ",RIGHT(A2,LEN(A2)-FIND(".",A2)-1))-1) -> 1 | F2: В святу й велику неділю Пасхи на Літургії | I2: lent | J2: 7 | L2: 7 | M2: =IFNA( VLOOKUP(LEFT(F2, IFERROR(FIND(" ", F2, 1),1) - 1), lists!$A$31:$B$37, 2, FALSE),"") | N2: =IFERROR(__xludf.DUMMYFUNCTION("IFNA(VLOOKUP(IFNA(REGEXEXTRACT(F2, ""(Пасхи|50-ці|посту)""),""""),lists!$A$39:$B$41,2,FALSE),"""")"),"pascha") -> pascha | O2: =IFERROR(__xludf.DUMMYFUNCTION("IFNA(REGEXEXTRACT(F2, ""\d{1,2}""),"""")"),"") | P2: =AND(OR(I2="",J2="",L2=""),H2="") -> FALSE
A3: Ів. 2 зач.; 1, 18-28. | B3: =LEFT(A3,FIND(".",A3)) -> Ів. | C3: iv | D3: =MID(A3,FIND(".",A3)+2,FIND(" ",RIGHT(A3,LEN(A3)-FIND(".",A3)-1))-1) -> 2 | F3: Понеділок світлого тижня | I3: pascha | J3: 1 | L3: 1 | M3: =IFNA( VLOOKUP(LEFT(F3, IFERROR(FIND(" ", F3, 1),1) - 1), lists!$A$31:$B$37, 2, FALSE),"") -> 1 | N3: =IFERROR(__xludf.DUMMYFUNCTION("IFNA(VLOOKUP(IFNA(REGEXEXTRACT(F3, ""(Пасхи|50-ці|посту)""),""""),lists!$A$39:$B$41,2,FALSE),"""")"),"") | O3: =IFERROR(__xludf.DUMMYFUNCTION("IFNA(REGEXEXTRACT(F3, ""\d{1,2}""),"""")"),"") | P3: =AND(OR(I3="",J3="",L3=""),H3="") -> FALSE
A4: Ів. 3 зач.; 1, 29-34. | B4: =LEFT(A4,FIND(".",A4)) -> Ів. | C4: iv | D4: =MID(A4,FIND(".",A4)+2,FIND(" ",RIGHT(A4,LEN(A4)-FIND(".",A4)-1))-1) -> 3 | F4: Другого дня Богоявлення на Літургії | H4: * | M4: =IFNA( VLOOKUP(LEFT(F4, IFERROR(FIND(" ", F4, 1),1) - 1), lists!$A$31:$B$37, 2, FALSE),"") | N4: =IFERROR(__xludf.DUMMYFUNCTION("IFNA(VLOOKUP(IFNA(REGEXEXTRACT(F4, ""(Пасхи|50-ці|посту)""),""""),lists!$A$39:$B$41,2,FALSE),"""")"),"") | O4: =IFERROR(__xludf.DUMMYFUNCTION("IFNA(REGEXEXTRACT(F4, ""\d{1,2}""),"""")"),"") | P4: =AND(OR(I4="",J4="",L4=""),H4="") -> FALSE
A5: Ів. 4 зач.; 1, 35-51. | B5: =LEFT(A5,FIND(".",A5)) -> Ів. | C5: iv | D5: =MID(A5,FIND(".",A5)+2,FIND(" ",RIGHT(A5,LEN(A5)-FIND(".",A5)-1))-1) -> 4 | F5: Середа світлого тижня. Це і апостолові Андрієві | H5: * | I5: pascha | J5: 1 | L5: 3 | M5: =IFNA( VLOOKUP(LEFT(F5, IFERROR(FIND(" ", F5, 1),1) - 1), lists!$A$31:$B$37, 2, FALSE),"") -> 3 | N5: =IFERROR(__xludf.DUMMYFUNCTION("IFNA(VLOOKUP(IFNA(REGEXEXTRACT(F5, ""(Пасхи|50-ці|посту)""),""""),lists!$A$39:$B$41,2,FALSE),"""")"),"") | O5: =IFERROR(__xludf.DUMMYFUNCTION("IFNA(REGEXEXTRACT(F5, ""\d{1,2}""),"""")"),"") | P5: =AND(OR(I5="",J5="",L5=""),H5="") -> FALSE
A6: Ів. 5 зач.; 1, 43-51. | B6: =LEFT(A6,FIND(".",A6)) -> Ів. | C6: iv | D6: =MID(A6,FIND(".",A6)+2,FIND(" ",RIGHT(A6,LEN(A6)-FIND(".",A6)-1))-1) -> 5 | F6: Неділя 1-ша посту. Це ж і святому апостолові Филипові | H6: * | I6: lent | J6: 1 | L6: 7 | M6: =IFNA( VLOOKUP(LEFT(F6, IFERROR(FIND(" ", F6, 1),1) - 1), lists!$A$31:$B$37, 2, FALSE),"") -> 7 | N6: =IFERROR(__xludf.DUMMYFUNCTION("IFNA(VLOOKUP(IFNA(REGEXEXTRACT(F6, ""(Пасхи|50-ці|посту)""),""""),lists!$A$39:$B$41,2,FALSE),"""")"),"lent") -> lent | O6: =IFERROR(__xludf.DUMMYFUNCTION("IFNA(REGEXEXTRACT(F6, ""\d{1,2}""),"""")"),"1") -> 1 | P6: =AND(OR(I6="",J6="",L6=""),H6="") -> FALSE
A7: Ів. 6 зач.; 2, 1-11. | B7: =LEFT(A7,FIND(".",A7)) -> Ів. | C7: iv | D7: =MID(A7,FIND(".",A7)+2,FIND(" ",RIGHT(A7,LEN(A7)-FIND(".",A7)-1))-1) -> 6 | F7: Понеділок 2-го тижня | I7: pascha | J7: 2 | L7: 1 | M7: =IFNA( VLOOKUP(LEFT(F7, IFERROR(FIND(" ", F7, 1),1) - 1), lists!$A$31:$B$37, 2, FALSE),"") -> 1 | N7: =IFERROR(__xludf.DUMMYFUNCTION("IFNA(VLOOKUP(IFNA(REGEXEXTRACT(F7, ""(Пасхи|50-ці|посту)""),""""),lists!$A$39:$B$41,2,FALSE),"""")"),"") | O7: =IFERROR(__xludf.DUMMYFUNCTION("IFNA(REGEXEXTRACT(F7, ""\d{1,2}""),"""")"),"2") -> 2 | P7: =AND(OR(I7="",J7="",L7=""),H7="") -> FALSE
A8: Ів. 7 зач.; 2, 12-22. | B8: =LEFT(A8,FIND(".",A8)) -> Ів. | C8: iv | D8: =MID(A8,FIND(".",A8)+2,FIND(" ",RIGHT(A8,LEN(A8)-FIND(".",A8)-1))-1) -> 7 | F8: П'ятниця світлого тижня | I8: pascha | J8: 1 | L8: 5 | M8: =IFNA( VLOOKUP(LEFT(F8, IFERROR(FIND(" ", F8, 1),1) - 1), lists!$A$31:$B$37, 2, FALSE),"") -> 5 | N8: =IFERROR(__xludf.DUMMYFUNCTION("IFNA(VLOOKUP(IFNA(REGEXEXTRACT(F8, ""(Пасхи|50-ці|посту)""),""""),lists!$A$39:$B$41,2,FALSE),"""")"),"") | O8: =IFERROR(__xludf.DUMMYFUNCTION("IFNA(REGEXEXTRACT(F8, ""\d{1,2}""),"""")"),"") | P8: =AND(OR(I8="",J8="",L8=""),H8="") -> FALSE
A9: Ів. 8 зач.; 3, 1-15. | B9: =LEFT(A9,FIND(".",A9)) -> Ів. | C9: iv | D9: =MID(A9,FIND(".",A9)+2,FIND(" ",RIGHT(A9,LEN(A9)-FIND(".",A9)-1))-1) -> 8 | F9: Четвер світлого тижня | I9: pascha | J9: 1 | L9: 4 | M9: =IFNA( VLOOKUP(LEFT(F9, IFERROR(FIND(" ", F9, 1),1) - 1), lists!$A$31:$B$37, 2, FALSE),"") -> 4 | N9: =IFERROR(__xludf.DUMMYFUNCTION("IFNA(VLOOKUP(IFNA(REGEXEXTRACT(F9, ""(Пасхи|50-ці|посту)""),""""),lists!$A$39:$B$41,2,FALSE),"""")"),"") | O9: =IFERROR(__xludf.DUMMYFUNCTION("IFNA(REGEXEXTRACT(F9, ""\d{1,2}""),"""")"),"") | P9: =AND(OR(I9="",J9="",L9=""),H9="") -> FALSE
A10: Ів. 9 зач.; 3, 13-17. | B10: =LEFT(A10,FIND(".",A10)) -> Ів. | C10: iv | D10: =MID(A10,FIND(".",A10)+2,FIND(" ",RIGHT(A10,LEN(A10)-FIND(".",A10)-1))-1) -> 9 | F10: Неділя перед Воздвиженням, Христа Людинолюбця | H10: * | L10: 7 | M10: =IFNA( VLOOKUP(LEFT(F10, IFERROR(FIND(" ", F10, 1),1) - 1), lists!$A$31:$B$37, 2, FALSE),"") -> 7 | N10: =IFERROR(__xludf.DUMMYFUNCTION("IFNA(VLOOKUP(IFNA(REGEXEXTRACT(F10, ""(Пасхи|50-ці|посту)""),""""),lists!$A$39:$B$41,2,FALSE),"""")"),"") | O10: =IFERROR(__xludf.DUMMYFUNCTION("IFNA(REGEXEXTRACT(F10, ""\d{1,2}""),"""")"),"") | P10: =AND(OR(I10="",J10="",L10=""),H10="") -> FALSE
A11: Ів. 10 зач.; 3, 16-21. | B11: =LEFT(A11,FIND(".",A11)) -> Ів. | C11: iv | D11: =MID(A11,FIND(".",A11)+2,FIND(" ",RIGHT(A11,LEN(A11)-FIND(".",A11)-1))-1) -> 10 | F11: Вівторок 2-го тижня | I11: pascha | J11: 2 | L11: 2 | M11: =IFNA( VLOOKUP(LEFT(F11, IFERROR(FIND(" ", F11, 1),1) - 1), lists!$A$31:$B$37, 2, FALSE),"") -> 2 | N11: =IFERROR(__xludf.DUMMYFUNCTION("IFNA(VLOOKUP(IFNA(REGEXEXTRACT(F11, ""(Пасхи|50-ці|посту)""),""""),lists!$A$39:$B$41,2,FALSE),"""")"),"") | O11: =IFERROR(__xludf.DUMMYFUNCTION("IFNA(REGEXEXTRACT(F11, ""\d{1,2}""),"""")"),"2") -> 2 | P11: =AND(OR(I11="",J11="",L11=""),H11="") -> FALSE
A12: Ів. 11 зач.; 3, 22-33. | B12: =LEFT(A12,FIND(".",A12)) -> Ів. | C12: iv | D12: =MID(A12,FIND(".",A12)+2,FIND(" ",RIGHT(A12,LEN(A12)-FIND(".",A12)-1))-1) -> 11 | F12: Субота світлого тижня | I12: pascha | J12: 1 | L12: 6 | M12: =IFNA( VLOOKUP(LEFT(F12, IFERROR(FIND(" ", F12, 1),1) - 1), lists!$A$31:$B$37, 2, FALSE),"") -> 6 | N12: =IFERROR(__xludf.DUMMYFUNCTION("IFNA(VLOOKUP(IFNA(REGEXEXTRACT(F12, ""(Пасхи|50-ці|посту)""),""""),lists!$A$39:$B$41,2,FALSE),"""")"),"") | O12: =IFERROR(__xludf.DUMMYFUNCTION("IFNA(REGEXEXTRACT(F12, ""\d{1,2}""),"""")"),"") | P12: =AND(OR(I12="",J12="",L12=""),H12="") -> FALSE
A13: Ів. 12 зач.; 4, 5-42. | B13: =LEFT(A13,FIND(".",A13)) -> Ів. | C13: iv | D13: =MID(A13,FIND(".",A13)+2,FIND(" ",RIGHT(A13,LEN(A13)-FIND(".",A13)-1))-1) -> 12 | F13: Неділя 5-та після Пасхи, про самарянку | I13: pascha | J13: 5 | L13: 7 | M13: =IFNA( VLOOKUP(LEFT(F13, IFERROR(FIND(" ", F13, 1),1) - 1), lists!$A$31:$B$37, 2, FALSE),"") -> 7 | N13: =IFERROR(__xludf.DUMMYFUNCTION("IFNA(VLOOKUP(IFNA(REGEXEXTRACT(F13, ""(Пасхи|50-ці|посту)""),""""),lists!$A$39:$B$41,2,FALSE),"""")"),"pascha") -> pascha | O13: =IFERROR(__xludf.DUMMYFUNCTION("IFNA(REGEXEXTRACT(F13, ""\d{1,2}""),"""")"),"5") -> 5 | P13: =AND(OR(I13="",J13="",L13=""),H13="") -> FALSE
A14: Ів. 13 зач.; 4, 46-54. | B14: =LEFT(A14,FIND(".",A14)) -> Ів. | C14: iv | D14: =MID(A14,FIND(".",A14)+2,FIND(" ",RIGHT(A14,LEN(A14)-FIND(".",A14)-1))-1) -> 13 | F14: Понеділок 3-го тижня | I14: pascha | J14: 3 | L14: 1 | M14: =IFNA( VLOOKUP(LEFT(F14, IFERROR(FIND(" ", F14, 1),1) - 1), lists!$A$31:$B$37, 2, FALSE),"") -> 1 | N14: =IFERROR(__xludf.DUMMYFUNCTION("IFNA(VLOOKUP(IFNA(REGEXEXTRACT(F14, ""(Пасхи|50-ці|посту)""),""""),lists!$A$39:$B$41,2,FALSE),"""")"),"") | O14: =IFERROR(__xludf.DUMMYFUNCTION("IFNA(REGEXEXTRACT(F14, ""\d{1,2}""),"""")"),"3") -> 3 | P14: =AND(OR(I14="",J14="",L14=""),H14="") -> FALSE
A15: Ів. 14 зач.; 5, 1-15. | B15: =LEFT(A15,FIND(".",A15)) -> Ів. | C15: iv | D15: =MID(A15,FIND(".",A15)+2,FIND(" ",RIGHT(A15,LEN(A15)-FIND(".",A15)-1))-1) -> 14 | E15: a | F15: Неділя 4-та, про розслабленого | I15: pascha | J15: 4 | L15: 7 | M15: =IFNA( VLOOKUP(LEFT(F15, IFERROR(FIND(" ", F15, 1),1) - 1), lists!$A$31:$B$37, 2, FALSE),"") -> 7 | N15: =IFERROR(__xludf.DUMMYFUNCTION("IFNA(VLOOKUP(IFNA(REGEXEXTRACT(F15, ""(Пасхи|50-ці|посту)""),""""),lists!$A$39:$B$41,2,FALSE),"""")"),"") | O15: =IFERROR(__xludf.DUMMYFUNCTION("IFNA(REGEXEXTRACT(F15, ""\d{1,2}""),"""")"),"4") -> 4 | P15: =AND(OR(I15="",J15="",L15=""),H15="") -> FALSE
A16: Ів. 14 зач.; 5, 1-4. | B16: =LEFT(A16,FIND(".",A16)) -> Ів. | C16: iv | D16: =MID(A16,FIND(".",A16)+2,FIND(" ",RIGHT(A16,LEN(A16)-FIND(".",A16)-1))-1) -> 14 | E16: b | F16: На освячення води | H16: * | M16: =IFNA( VLOOKUP(LEFT(F16, IFERROR(FIND(" ", F16, 1),1) - 1), lists!$A$31:$B$37, 2, FALSE),"") | N16: =IFERROR(__xludf.DUMMYFUNCTION("IFNA(VLOOKUP(IFNA(REGEXEXTRACT(F16, ""(Пасхи|50-ці|посту)""),""""),lists!$A$39:$B$41,2,FALSE),"""")"),"") | O16: =IFERROR(__xludf.DUMMYFUNCTION("IFNA(REGEXEXTRACT(F16, ""\d{1,2}""),"""")"),"") | P16: =AND(OR(I16="",J16="",L16=""),H16="") -> FALSE
A17: Ів. 15 зач.; 5, 17-24. | B17: =LEFT(A17,FIND(".",A17)) -> Ів. | C17: iv | D17: =MID(A17,FIND(".",A17)+2,FIND(" ",RIGHT(A17,LEN(A17)-FIND(".",A17)-1))-1) -> 15 | F17: Середа 2-го тижня. Це ж і мертвим в понеділок | H17: * | I17: pascha | J17: 2 | L17: 3 | M17: =IFNA( VLOOKUP(LEFT(F17, IFERROR(FIND(" ", F17, 1),1) - 1), lists!$A$31:$B$37, 2, FALSE),"") -> 3 | N17: =IFERROR(__xludf.DUMMYFUNCTION("IFNA(VLOOKUP(IFNA(REGEXEXTRACT(F17, ""(Пасхи|50-ці|посту)""),""""),lists!$A$39:$B$41,2,FALSE),"""")"),"") | O17: =IFERROR(__xludf.DUMMYFUNCTION("IFNA(REGEXEXTRACT(F17, ""\d{1,2}""),"""")"),"2") -> 2 | P17: =AND(OR(I17="",J17="",L17=""),H17="") -> FALSE
A18: Ів. 16 зач.; 5, 24-30. | B18: =LEFT(A18,FIND(".",A18)) -> Ів. | C18: iv | D18: =MID(A18,FIND(".",A18)+2,FIND(" ",RIGHT(A18,LEN(A18)-FIND(".",A18)-1))-1) -> 16 | F18: Четвер 2-го тижня. Це ж і мертвим у вівторок і в суботу. | H18: * | I18: pascha | J18: 2 | L18: 4 | M18: =IFNA( VLOOKUP(LEFT(F18, IFERROR(FIND(" ", F18, 1),1) - 1), lists!$A$31:$B$37, 2, FALSE),"") -> 4 | N18: =IFERROR(__xludf.DUMMYFUNCTION("IFNA(VLOOKUP(IFNA(REGEXEXTRACT(F18, ""(Пасхи|50-ці|посту)""),""""),lists!$A$39:$B$41,2,FALSE),"""")"),"") | O18: =IFERROR(__xludf.DUMMYFUNCTION("IFNA(REGEXEXTRACT(F18, ""\d{1,2}""),"""")"),"2") -> 2 | P18: =AND(OR(I18="",J18="",L18=""),H18="") -> FALSE
A19: Ів. 17 зач.; 5, 30 – 6, 2. | B19: =LEFT(A19,FIND(".",A19)) -> Ів. | C19: iv | D19: =MID(A19,FIND(".",A19)+2,FIND(" ",RIGHT(A19,LEN(A19)-FIND(".",A19)-1))-1) -> 17 | F19: П'ятниця 2-го тижня | I19: pascha | J19: 2 | L19: 5 | M19: =IFNA( VLOOKUP(LEFT(F19, IFERROR(FIND(" ", F19, 1),1) - 1), lists!$A$31:$B$37, 2, FALSE),"") -> 5 | N19: =IFERROR(__xludf.DUMMYFUNCTION("IFNA(VLOOKUP(IFNA(REGEXEXTRACT(F19, ""(Пасхи|50-ці|посту)""),""""),lists!$A$39:$B$41,2,FALSE),"""")"),"") | O19: =IFERROR(__xludf.DUMMYFUNCTION("IFNA(REGEXEXTRACT(F19, ""\d{1,2}""),"""")"),"2") -> 2 | P19: =AND(OR(I19="",J19="",L19=""),H19="") -> FALSE
A20: Ів. 18 зач.; 6, 5-14. | B20: =LEFT(A20,FIND(".",A20)) -> Ів. | C20: iv | D20: =MID(A20,FIND(".",A20)+2,FIND(" ",RIGHT(A20,LEN(A20)-FIND(".",A20)-1))-1) -> 18 | F20: Середа 5-го тижня | I20: pascha | J20: 5 | L20: 3 | M20: =IFNA( VLOOKUP(LEFT(F20, IFERROR(FIND(" ", F20, 1),1) - 1), lists!$A$31:$B$37, 2, FALSE),"") -> 3 | N20: =IFERROR(__xludf.DUMMYFUNCTION("IFNA(VLOOKUP(IFNA(REGEXEXTRACT(F20, ""(Пасхи|50-ці|посту)""),""""),lists!$A$39:$B$41,2,FALSE),"""")"),"") | O20: =IFERROR(__xludf.DUMMYFUNCTION("IFNA(REGEXEXTRACT(F20, ""\d{1,2}""),"""")"),"5") -> 5 | P20: =AND(OR(I20="",J20="",L20=""),H20="") -> FALSE
A21: Ів. 19 зач.; 6, 14-27. | B21: =LEFT(A21,FIND(".",A21)) -> Ів. | C21: iv | D21: =MID(A21,FIND(".",A21)+2,FIND(" ",RIGHT(A21,LEN(A21)-FIND(".",A21)-1))-1) -> 19 | F21: Субота 2-га після Пасхи | I21: pascha | J21: 2 | L21: 6 | M21: =IFNA( VLOOKUP(LEFT(F21, IFERROR(FIND(" ", F21, 1),1) - 1), lists!$A$31:$B$37, 2, FALSE),"") -> 6 | N21: =IFERROR(__xludf.DUMMYFUNCTION("IFNA(VLOOKUP(IFNA(REGEXEXTRACT(F21, ""(Пасхи|50-ці|посту)""),""""),lists!$A$39:$B$41,2,FALSE),"""")"),"pascha") -> pascha | O21: =IFERROR(__xludf.DUMMYFUNCTION("IFNA(REGEXEXTRACT(F21, ""\d{1,2}""),"""")"),"2") -> 2 | P21: =AND(OR(I21="",J21="",L21=""),H21="") -> FALSE
A22: Ів. 20 зач.; 6, 27-33. | B22: =LEFT(A22,FIND(".",A22)) -> Ів. | C22: iv | D22: =MID(A22,FIND(".",A22)+2,FIND(" ",RIGHT(A22,LEN(A22)-FIND(".",A22)-1))-1) -> 20 | F22: Вівторок 3-го тижня | I22: pascha | J22: 3 | L22: 2 | M22: =IFNA( VLOOKUP(LEFT(F22, IFERROR(FIND(" ", F22, 1),1) - 1), lists!$A$31:$B$37, 2, FALSE),"") -> 2 | N22: =IFERROR(__xludf.DUMMYFUNCTION("IFNA(VLOOKUP(IFNA(REGEXEXTRACT(F22, ""(Пасхи|50-ці|посту)""),""""),lists!$A$39:$B$41,2,FALSE),"""")"),"") | O22: =IFERROR(__xludf.DUMMYFUNCTION("IFNA(REGEXEXTRACT(F22, ""\d{1,2}""),"""")"),"3") -> 3 | P22: =AND(OR(I22="",J22="",L22=""),H22="") -> FALSE
A23: Ів. 21 зач.; 6, 35-39. | B23: =LEFT(A23,FIND(".",A23)) -> Ів. | C23: iv | D23: =MID(A23,FIND(".",A23)+2,FIND(" ",RIGHT(A23,LEN(A23)-FIND(".",A23)-1))-1) -> 21 | F23: Середа 3-го тижня. Це і мертвим у середу | H23: * | I23: pascha | J23: 3 | L23: 3 | M23: =IFNA( VLOOKUP(LEFT(F23, IFERROR(FIND(" ", F23, 1),1) - 1), lists!$A$31:$B$37, 2, FALSE),"") -> 3 | N23: =IFERROR(__xludf.DUMMYFUNCTION("IFNA(VLOOKUP(IFNA(REGEXEXTRACT(F23, ""(Пасхи|50-ці|посту)""),""""),lists!$A$39:$B$41,2,FALSE),"""")"),"") | O23: =IFERROR(__xludf.DUMMYFUNCTION("IFNA(REGEXEXTRACT(F23, ""\d{1,2}""),"""")"),"3") -> 3 | P23: =AND(OR(I23="",J23="",L23=""),H23="") -> FALSE
A24: Ів. 22 зач.; 6, 40-44. | B24: =LEFT(A24,FIND(".",A24)) -> Ів. | C24: iv | D24: =MID(A24,FIND(".",A24)+2,FIND(" ",RIGHT(A24,LEN(A24)-FIND(".",A24)-1))-1) -> 22 | F24: Четвер 3-го тижня | I24: pascha | J24: 3 | L24: 4 | M24: =IFNA( VLOOKUP(LEFT(F24, IFERROR(FIND(" ", F24, 1),1) - 1), lists!$A$31:$B$37, 2, FALSE),"") -> 4 | N24: =IFERROR(__xludf.DUMMYFUNCTION("IFNA(VLOOKUP(IFNA(REGEXEXTRACT(F24, ""(Пасхи|50-ці|посту)""),""""),lists!$A$39:$B$41,2,FALSE),"""")"),"") | O24: =IFERROR(__xludf.DUMMYFUNCTION("IFNA(REGEXEXTRACT(F24, ""\d{1,2}""),"""")"),"3") -> 3 | P24: =AND(OR(I24="",J24="",L24=""),H24="") -> FALSE
A25: Ів. 23 зач.; 6, 48-54. | B25: =LEFT(A25,FIND(".",A25)) -> Ів. | C25: iv | D25: =MID(A25,FIND(".",A25)+2,FIND(" ",RIGHT(A25,LEN(A25)-FIND(".",A25)-1))-1) -> 23 | F25: П'ятниця 3-го тижня. Також на Пресвятої Євхаристії на Літургії. | I25: pascha | J25: 3 | L25: 5 | M25: =IFNA( VLOOKUP(LEFT(F25, IFERROR(FIND(" ", F25, 1),1) - 1), lists!$A$31:$B$37, 2, FALSE),"") -> 5 | N25: =IFERROR(__xludf.DUMMYFUNCTION("IFNA(VLOOKUP(IFNA(REGEXEXTRACT(F25, ""(Пасхи|50-ці|посту)""),""""),lists!$A$39:$B$41,2,FALSE),"""")"),"") | O25: =IFERROR(__xludf.DUMMYFUNCTION("IFNA(REGEXEXTRACT(F25, ""\d{1,2}""),"""")"),"3") -> 3 | P25: =AND(OR(I25="",J25="",L25=""),H25="") -> FALSE
A26: Ів. 24 зач.; 6, 55-58. | B26: =LEFT(A26,FIND(".",A26)) -> Ів. | C26: iv | D26: =MID(A26,FIND(".",A26)+2,FIND(" ",RIGHT(A26,LEN(A26)-FIND(".",A26)-1))-1) -> 24 | E26: a | F26: На Пресвятої Євхаристії на Утрені.
A27: Ів. 24 зач.; 6, 56-69. | B27: =LEFT(A27,FIND(".",A27)) -> Ів. | C27: iv | D27: =MID(A27,FIND(".",A27)+2,FIND(" ",RIGHT(A27,LEN(A27)-FIND(".",A27)-1))-1) -> 24 | E27: b | F27: Понеділок 4-го тижня | I27: pascha | J27: 4 | L27: 1 | M27: =IFNA( VLOOKUP(LEFT(F27, IFERROR(FIND(" ", F27, 1),1) - 1), lists!$A$31:$B$37, 2, FALSE),"") -> 1 | N27: =IFERROR(__xludf.DUMMYFUNCTION("IFNA(VLOOKUP(IFNA(REGEXEXTRACT(F27, ""(Пасхи|50-ці|посту)""),""""),lists!$A$39:$B$41,2,FALSE),"""")"),"") | O27: =IFERROR(__xludf.DUMMYFUNCTION("IFNA(REGEXEXTRACT(F27, ""\d{1,2}""),"""")"),"4") -> 4 | P27: =AND(OR(I27="",J27="",L27=""),H27="") -> FALSE
A28: Ів. 25 зач.; 7, 1-13. | B28: =LEFT(A28,FIND(".",A28)) -> Ів. | C28: iv | D28: =MID(A28,FIND(".",A28)+2,FIND(" ",RIGHT(A28,LEN(A28)-FIND(".",A28)-1))-1) -> 25 | F28: Вівторок 4-го тижня | I28: pascha | J28: 4 | L28: 2 | M28: =IFNA( VLOOKUP(LEFT(F28, IFERROR(FIND(" ", F28, 1),1) - 1), lists!$A$31:$B$37, 2, FALSE),"") -> 2 | N28: =IFERROR(__xludf.DUMMYFUNCTION("IFNA(VLOOKUP(IFNA(REGEXEXTRACT(F28, ""(Пасхи|50-ці|посту)""),""""),lists!$A$39:$B$41,2,FALSE),"""")"),"") | O28: =IFERROR(__xludf.DUMMYFUNCTION("IFNA(REGEXEXTRACT(F28, ""\d{1,2}""),"""")"),"4") -> 4 | P28: =AND(OR(I28="",J28="",L28=""),H28="") -> FALSE
A29: Ів. 26 зач.; 7, 14-30. | B29: =LEFT(A29,FIND(".",A29)) -> Ів. | C29: iv | D29: =MID(A29,FIND(".",A29)+2,FIND(" ",RIGHT(A29,LEN(A29)-FIND(".",A29)-1))-1) -> 26 | F29: Середа 4-го тижня | I29: pascha | J29: 4 | L29: 3 | M29: =IFNA( VLOOKUP(LEFT(F29, IFERROR(FIND(" ", F29, 1),1) - 1), lists!$A$31:$B$37, 2, FALSE),"") -> 3 | N29: =IFERROR(__xludf.DUMMYFUNCTION("IFNA(VLOOKUP(IFNA(REGEXEXTRACT(F29, ""(Пасхи|50-ці|посту)""),""""),lists!$A$39:$B$41,2,FALSE),"""")"),"") | O29: =IFERROR(__xludf.DUMMYFUNCTION("IFNA(REGEXEXTRACT(F29, ""\d{1,2}""),"""")"),"4") -> 4 | P29: =AND(OR(I29="",J29="",L29=""),H29="") -> FALSE
A30: Ів. 27 зач.; 7, 37-52; 8, 12. | B30: =LEFT(A30,FIND(".",A30)) -> Ів. | C30: iv | D30: =MID(A30,FIND(".",A30)+2,FIND(" ",RIGHT(A30,LEN(A30)-FIND(".",A30)-1))-1) -> 27 | F30: Неділя 8-ма, П'ятидесятниця | H30: liturgy | I30: pascha | J30: 7 | L30: 7 | M30: =IFNA( VLOOKUP(LEFT(F30, IFERROR(FIND(" ", F30, 1),1) - 1), lists!$A$31:$B$37, 2, FALSE),"") -> 7 | N30: =IFERROR(__xludf.DUMMYFUNCTION("IFNA(VLOOKUP(IFNA(REGEXEXTRACT(F30, ""(Пасхи|50-ці|посту)""),""""),lists!$A$39:$B$41,2,FALSE),"""")"),"") | O30: =IFERROR(__xludf.DUMMYFUNCTION("IFNA(REGEXEXTRACT(F30, ""\d{1,2}""),"""")"),"8") -> 8 | P30: =AND(OR(I30="",J30="",L30=""),H30="") -> FALSE
A31: Ів. 28 зач.; 8, 3-11. | B31: =LEFT(A31,FIND(".",A31)) -> Ів. | C31: iv | D31: =MID(A31,FIND(".",A31)+2,FIND(" ",RIGHT(A31,LEN(A31)-FIND(".",A31)-1))-1) -> 28 | F31: Святим жінкам | H31: * | I31: pascha | M31: =IFNA( VLOOKUP(LEFT(F31, IFERROR(FIND(" ", F31, 1),1) - 1), lists!$A$31:$B$37, 2, FALSE),"") | N31: =IFERROR(__xludf.DUMMYFUNCTION("IFNA(VLOOKUP(IFNA(REGEXEXTRACT(F31, ""(Пасхи|50-ці|посту)""),""""),lists!$A$39:$B$41,2,FALSE),"""")"),"") | O31: =IFERROR(__xludf.DUMMYFUNCTION("IFNA(REGEXEXTRACT(F31, ""\d{1,2}""),"""")"),"") | P31: =AND(OR(I31="",J31="",L31=""),H31="") -> FALSE
A32: Ів. 29 зач.; 8, 12-20. | B32: =LEFT(A32,FIND(".",A32)) -> Ів. | C32: iv | D32: =MID(A32,FIND(".",A32)+2,FIND(" ",RIGHT(A32,LEN(A32)-FIND(".",A32)-1))-1) -> 29 | F32: Четвер 4-го тижня | I32: pascha | J32: 4 | L32: 4 | M32: =IFNA( VLOOKUP(LEFT(F32, IFERROR(FIND(" ", F32, 1),1) - 1), lists!$A$31:$B$37, 2, FALSE),"") -> 4 | N32: =IFERROR(__xludf.DUMMYFUNCTION("IFNA(VLOOKUP(IFNA(REGEXEXTRACT(F32, ""(Пасхи|50-ці|посту)""),""""),lists!$A$39:$B$41,2,FALSE),"""")"),"") | O32: =IFERROR(__xludf.DUMMYFUNCTION("IFNA(REGEXEXTRACT(F32, ""\d{1,2}""),"""")"),"4") -> 4 | P32: =AND(OR(I32="",J32="",L32=""),H32="") -> FALSE
A33: Ів. 30 зач.; 8, 21-30. | B33: =LEFT(A33,FIND(".",A33)) -> Ів. | C33: iv | D33: =MID(A33,FIND(".",A33)+2,FIND(" ",RIGHT(A33,LEN(A33)-FIND(".",A33)-1))-1) -> 30 | F33: П'ятниця 4-го тижня. Це ж і в суботу після Воздвиження | I33: pascha | J33: 4 | L33: 5 | M33: =IFNA( VLOOKUP(LEFT(F33, IFERROR(FIND(" ", F33, 1),1) - 1), lists!$A$31:$B$37, 2, FALSE),"") -> 5 | N33: =IFERROR(__xludf.DUMMYFUNCTION("IFNA(VLOOKUP(IFNA(REGEXEXTRACT(F33, ""(Пасхи|50-ці|посту)""),""""),lists!$A$39:$B$41,2,FALSE),"""")"),"") | O33: =IFERROR(__xludf.DUMMYFUNCTION("IFNA(REGEXEXTRACT(F33, ""\d{1,2}""),"""")"),"4") -> 4 | P33: =AND(OR(I33="",J33="",L33=""),H33="") -> FALSE
A34: Ів. 31 зач.; 8, 31-42. | B34: =LEFT(A34,FIND(".",A34)) -> Ів. | C34: iv | D34: =MID(A34,FIND(".",A34)+2,FIND(" ",RIGHT(A34,LEN(A34)-FIND(".",A34)-1))-1) -> 31 | F34: Субота 4-го тижня | I34: pascha | J34: 4 | L34: 6 | M34: =IFNA( VLOOKUP(LEFT(F34, IFERROR(FIND(" ", F34, 1),1) - 1), lists!$A$31:$B$37, 2, FALSE),"") -> 6 | N34: =IFERROR(__xludf.DUMMYFUNCTION("IFNA(VLOOKUP(IFNA(REGEXEXTRACT(F34, ""(Пасхи|50-ці|посту)""),""""),lists!$A$39:$B$41,2,FALSE),"""")"),"") | O34: =IFERROR(__xludf.DUMMYFUNCTION("IFNA(REGEXEXTRACT(F34, ""\d{1,2}""),"""")"),"4") -> 4 | P34: =AND(OR(I34="",J34="",L34=""),H34="") -> FALSE
A35: Ів. 32 зач.; 8, 42-51. | B35: =LEFT(A35,FIND(".",A35)) -> Ів. | C35: iv | D35: =MID(A35,FIND(".",A35)+2,FIND(" ",RIGHT(A35,LEN(A35)-FIND(".",A35)-1))-1) -> 32 | F35: Понеділок 5-го тижня | I35: pascha | J35: 5 | L35: 1 | M35: =IFNA( VLOOKUP(LEFT(F35, IFERROR(FIND(" ", F35, 1),1) - 1), lists!$A$31:$B$37, 2, FALSE),"") -> 1 | N35: =IFERROR(__xludf.DUMMYFUNCTION("IFNA(VLOOKUP(IFNA(REGEXEXTRACT(F35, ""(Пасхи|50-ці|посту)""),""""),lists!$A$39:$B$41,2,FALSE),"""")"),"") | O35: =IFERROR(__xludf.DUMMYFUNCTION("IFNA(REGEXEXTRACT(F35, ""\d{1,2}""),"""")"),"5") -> 5 | P35: =AND(OR(I35="",J35="",L35=""),H35="") -> FALSE
A36: Ів. 33 зач.; 8, 51-59. | B36: =LEFT(A36,FIND(".",A36)) -> Ів. | C36: iv | D36: =MID(A36,FIND(".",A36)+2,FIND(" ",RIGHT(A36,LEN(A36)-FIND(".",A36)-1))-1) -> 33 | F36: Вівторок 5-го тижня | I36: pascha | J36: 5 | L36: 2 | M36: =IFNA( VLOOKUP(LEFT(F36, IFERROR(FIND(" ", F36, 1),1) - 1), lists!$A$31:$B$37, 2, FALSE),"") -> 2 | N36: =IFERROR(__xludf.DUMMYFUNCTION("IFNA(VLOOKUP(IFNA(REGEXEXTRACT(F36, ""(Пасхи|50-ці|посту)""),""""),lists!$A$39:$B$41,2,FALSE),"""")"),"") | O36: =IFERROR(__xludf.DUMMYFUNCTION("IFNA(REGEXEXTRACT(F36, ""\d{1,2}""),"""")"),"5") -> 5 | P36: =AND(OR(I36="",J36="",L36=""),H36="") -> FALSE
A37: Ів. 34 зач.; 9, 1-38. | B37: =LEFT(A37,FIND(".",A37)) -> Ів. | C37: iv | D37: =MID(A37,FIND(".",A37)+2,FIND(" ",RIGHT(A37,LEN(A37)-FIND(".",A37)-1))-1) -> 34 | F37: Неділя 6-та, про сліпородженого | I37: pascha | J37: 5 | L37: 7 | M37: =IFNA( VLOOKUP(LEFT(F37, IFERROR(FIND(" ", F37, 1),1) - 1), lists!$A$31:$B$37, 2, FALSE),"") -> 7 | N37: =IFERROR(__xludf.DUMMYFUNCTION("IFNA(VLOOKUP(IFNA(REGEXEXTRACT(F37, ""(Пасхи|50-ці|посту)""),""""),lists!$A$39:$B$41,2,FALSE),"""")"),"") | O37: =IFERROR(__xludf.DUMMYFUNCTION("IFNA(REGEXEXTRACT(F37, ""\d{1,2}""),"""")"),"6") -> 6 | P37: =AND(OR(I37="",J37="",L37=""),H37="") -> FALSE
A38: Ів. 35 зач.; 9, 39 – 10, 9. | B38: =LEFT(A38,FIND(".",A38)) -> Ів. | C38: iv | D38: =MID(A38,FIND(".",A38)+2,FIND(" ",RIGHT(A38,LEN(A38)-FIND(".",A38)-1))-1) -> 35 | E38: a | F38: Четвер 5-го тижня | I38: pascha | J38: 5 | L38: 4 | M38: =IFNA( VLOOKUP(LEFT(F38, IFERROR(FIND(" ", F38, 1),1) - 1), lists!$A$31:$B$37, 2, FALSE),"") -> 4 | N38: =IFERROR(__xludf.DUMMYFUNCTION("IFNA(VLOOKUP(IFNA(REGEXEXTRACT(F38, ""(Пасхи|50-ці|посту)""),""""),lists!$A$39:$B$41,2,FALSE),"""")"),"") | O38: =IFERROR(__xludf.DUMMYFUNCTION("IFNA(REGEXEXTRACT(F38, ""\d{1,2}""),"""")"),"5") -> 5 | P38: =AND(OR(I38="",J38="",L38=""),H38="") -> FALSE
A39: Ів. 35 зач.; 10, 1-9. | B39: =LEFT(A39,FIND(".",A39)) -> Ів. | C39: iv | D39: =MID(A39,FIND(".",A39)+2,FIND(" ",RIGHT(A39,LEN(A39)-FIND(".",A39)-1))-1) -> 35 | E39: b | F39: Святителям на Утрені | H39: * | M39: =IFNA( VLOOKUP(LEFT(F39, IFERROR(FIND(" ", F39, 1),1) - 1), lists!$A$31:$B$37, 2, FALSE),"") | N39: =IFERROR(__xludf.DUMMYFUNCTION("IFNA(VLOOKUP(IFNA(REGEXEXTRACT(F39, ""(Пасхи|50-ці|посту)""),""""),lists!$A$39:$B$41,2,FALSE),"""")"),"") | O39: =IFERROR(__xludf.DUMMYFUNCTION("IFNA(REGEXEXTRACT(F39, ""\d{1,2}""),"""")"),"") | P39: =AND(OR(I39="",J39="",L39=""),H39="") -> FALSE
